Workbook

Sheet Roster
A1: employee_id | B1: first_name | C1: last_name | D1: email | E1: title | F1: level_code | G1: level_band | H1: practice_group | I1: sub_team | J1: office_city | K1: country | L1: region | M1: office_type | N1: work_model | O1: hire_date | P1: tenure_years | Q1: joined_after_relaunch | R1: manager_id | S1: manager_name | T1: dms_role | U1: cohort_key
A2: VL-1001 | B2: Simon | C2: Rasmussen | D2: simon.rasmussen@vandelay.example | E2: General Counsel | F2: L1 | G2: Lawyer - Leadership | H2: Office of the General Counsel | J2: New York | K2: United States | L2: Americas - US | M2: HQ | N2: Hybrid | O2: 39407 | P2: =ROUND((About!$B$3-O2)/365.25,1) -> 18.8 | Q2: =IF(O2>About!$B$4,"Yes","No") -> No | S2: =IF(R2="","",INDEX($B$2:$B$231,MATCH(R2,$A$2:$A$231,0))&" "&INDEX($C$2:$C$231,MATCH(R2,$A$2:$A$231,0))) | T2: Standard | U2: =H2&" | "&G2 -> Office of the General Counsel | Lawyer - Leadership
A3: VL-1216 | B3: Owen | C3: Whitfield | D3: owen.whitfield@vandelay.example | E3: Executive Assistant | F3: EA | G3: Executive Assistant | H3: Office of the General Counsel | I3: Executive Support | J3: New York | K3: United States | L3: Americas - US | M3: HQ | N3: Office | O3: 45836 | P3: =ROUND((About!$B$3-O3)/365.25,1) -> 1.2 | Q3: =IF(O3>About!$B$4,"Yes","No") -> Yes | R3: VL-1001 | S3: =IF(R3="","",INDEX($B$2:$B$231,MATCH(R3,$A$2:$A$231,0))&" "&INDEX($C$2:$C$231,MATCH(R3,$A$2:$A$231,0))) -> Simon Rasmussen | T3: Standard | U3: =H3&" | "&G3 -> Office of the General Counsel | Executive Assistant
A4: VL-1217 | B4: Ruth | C4: Osman | D4: ruth.osman@vandelay.example | E4: Executive Assistant | F4: EA | G4: Executive Assistant | H4: Office of the General Counsel | I4: Executive Support | J4: New York | K4: United States | L4: Americas - US | M4: HQ | N4: Hybrid | O4: 43226 | P4: =ROUND((About!$B$3-O4)/365.25,1) -> 8.3 | Q4: =IF(O4>About!$B$4,"Yes","No") -> No | R4: VL-1001 | S4: =IF(R4="","",INDEX($B$2:$B$231,MATCH(R4,$A$2:$A$231,0))&" "&INDEX($C$2:$C$231,MATCH(R4,$A$2:$A$231,0))) -> Simon Rasmussen | T4: Standard | U4: =H4&" | "&G4 -> Office of the General Counsel | Executive Assistant
A5: VL-1002 | B5: Aisha | C5: Villanueva | D5: aisha.villanueva@vandelay.example | E5: Deputy General Counsel, Commercial & Transactions | F5: L2 | G5: Lawyer - Leadership | H5: Commercial & Transactions | J5: New York | K5: United States | L5: Americas - US | M5: HQ | N5: Hybrid | O5: 39235 | P5: =ROUND((About!$B$3-O5)/365.25,1) -> 19.3 | Q5: =IF(O5>About!$B$4,"Yes","No") -> No | R5: VL-1001 | S5: =IF(R5="","",INDEX($B$2:$B$231,MATCH(R5,$A$2:$A$231,0))&" "&INDEX($C$2:$C$231,MATCH(R5,$A$2:$A$231,0))) -> Simon Rasmussen | T5: Standard | U5: =H5&" | "&G5 -> Commercial & Transactions | Lawyer - Leadership
A6: VL-1010 | B6: Solveig | C6: Ramanathan | D6: solveig.ramanathan@vandelay.example | E6: Attorney | F6: L5 | G6: Lawyer - Junior | H6: Commercial & Transactions | J6: London | K6: United Kingdom | L6: EMEA | M6: International office | N6: Hybrid | O6: 43467 | P6: =ROUND((About!$B$3-O6)/365.25,1) -> 7.7 | Q6: =IF(O6>About!$B$4,"Yes","No") -> No | R6: VL-1002 | S6: =IF(R6="","",INDEX($B$2:$B$231,MATCH(R6,$A$2:$A$231,0))&" "&INDEX($C$2:$C$231,MATCH(R6,$A$2:$A$231,0))) -> Aisha Villanueva | T6: Standard | U6: =H6&" | "&G6 -> Commercial & Transactions | Lawyer - Junior
A7: VL-1011 | B7: George | C7: Byrne | D7: george.byrne@vandelay.example | E7: Attorney | F7: L5 | G7: Lawyer - Junior | H7: Commercial & Transactions | J7: London | K7: United Kingdom | L7: EMEA | M7: International office | N7: Office | O7: 46024 | P7: =ROUND((About!$B$3-O7)/365.25,1) -> 0.7 | Q7: =IF(O7>About!$B$4,"Yes","No") -> Yes | R7: VL-1002 | S7: =IF(R7="","",INDEX($B$2:$B$231,MATCH(R7,$A$2:$A$231,0))&" "&INDEX($C$2:$C$231,MATCH(R7,$A$2:$A$231,0))) -> Aisha Villanueva | T7: Standard | U7: =H7&" | "&G7 -> Commercial & Transactions | Lawyer - Junior
A8: VL-1012 | B8: Zainab | C8: Rasmussen | D8: zainab.rasmussen@vandelay.example | E8: Counsel | F8: L4 | G8: Lawyer - Mid | H8: Commercial & Transactions | J8: Singapore | K8: Singapore | L8: APAC | M8: International office | N8: Hybrid | O8: 37915 | P8: =ROUND((About!$B$3-O8)/365.25,1) -> 22.9 | Q8: =IF(O8>About!$B$4,"Yes","No") -> No | R8: VL-1002 | S8: =IF(R8="","",INDEX($B$2:$B$231,MATCH(R8,$A$2:$A$231,0))&" "&INDEX($C$2:$C$231,MATCH(R8,$A$2:$A$231,0))) -> Aisha Villanueva | T8: Standard | U8: =H8&" | "&G8 -> Commercial & Transactions | Lawyer - Mid
A9: VL-1013 | B9: Rohan | C9: Okafor | D9: rohan.okafor@vandelay.example | E9: Attorney | F9: L5 | G9: Lawyer - Junior | H9: Commercial & Transactions | J9: London | K9: United Kingdom | L9: EMEA | M9: International office | N9: Hybrid | O9: 42366 | P9: =ROUND((About!$B$3-O9)/365.25,1) -> 10.7 | Q9: =IF(O9>About!$B$4,"Yes","No") -> No | R9: VL-1002 | S9: =IF(R9="","",INDEX($B$2:$B$231,MATCH(R9,$A$2:$A$231,0))&" "&INDEX($C$2:$C$231,MATCH(R9,$A$2:$A$231,0))) -> Aisha Villanueva | T9: Standard | U9: =H9&" | "&G9 -> Commercial & Transactions | Lawyer - Junior
A10: VL-1014 | B10: Hao | C10: Krishnan | D10: hao.krishnan@vandelay.example | E10: Counsel | F10: L4 | G10: Lawyer - Mid | H10: Commercial & Transactions | J10: Singapore | K10: Singapore | L10: APAC | M10: International office | N10: Hybrid | O10: 43621 | P10: =ROUND((About!$B$3-O10)/365.25,1) -> 7.3 | Q10: =IF(O10>About!$B$4,"Yes","No") -> No | R10: VL-1002 | S10: =IF(R10="","",INDEX($B$2:$B$231,MATCH(R10,$A$2:$A$231,0))&" "&INDEX($C$2:$C$231,MATCH(R10,$A$2:$A$231,0))) -> Aisha Villanueva | T10: Standard | U10: =H10&" | "&G10 -> Commercial & Transactions | Lawyer - Mid
A11: VL-1015 | B11: Bram | C11: Contreras | D11: bram.contreras@vandelay.example | E11: Counsel | F11: L4 | G11: Lawyer - Mid | H11: Commercial & Transactions | J11: Atlanta | K11: United States | L11: Americas - US | M11: Regional office | N11: Hybrid | O11: 44187 | P11: =ROUND((About!$B$3-O11)/365.25,1) -> 5.7 | Q11: =IF(O11>About!$B$4,"Yes","No") -> No | R11: VL-1002 | S11: =IF(R11="","",INDEX($B$2:$B$231,MATCH(R11,$A$2:$A$231,0))&" "&INDEX($C$2:$C$231,MATCH(R11,$A$2:$A$231,0))) -> Aisha Villanueva | T11: Standard | U11: =H11&" | "&G11 -> Commercial & Transactions | Lawyer - Mid
A12: VL-1016 | B12: Daniel | C12: Fontaine | D12: daniel.fontaine@vandelay.example | E12: Counsel | F12: L4 | G12: Lawyer - Mid | H12: Commercial & Transactions | J12: Houston | K12: United States | L12: Americas - US | M12: Regional office | N12: Hybrid | O12: 45996 | P12: =ROUND((About!$B$3-O12)/365.25,1) -> 0.8 | Q12: =IF(O12>About!$B$4,"Yes","No") -> Yes | R12: VL-1002 | S12: =IF(R12="","",INDEX($B$2:$B$231,MATCH(R12,$A$2:$A$231,0))&" "&INDEX($C$2:$C$231,MATCH(R12,$A$2:$A$231,0))) -> Aisha Villanueva | T12: Standard | U12: =H12&" | "&G12 -> Commercial & Transactions | Lawyer - Mid
A13: VL-1017 | B13: Lorenzo | C13: Alvarado | D13: lorenzo.alvarado@vandelay.example | E13: Counsel | F13: L4 | G13: Lawyer - Mid | H13: Commercial & Transactions | J13: New York | K13: United States | L13: Americas - US | M13: HQ | N13: Office | O13: 43382 | P13: =ROUND((About!$B$3-O13)/365.25,1) -> 7.9 | Q13: =IF(O13>About!$B$4,"Yes","No") -> No | R13: VL-1002 | S13: =IF(R13="","",INDEX($B$2:$B$231,MATCH(R13,$A$2:$A$231,0))&" "&INDEX($C$2:$C$231,MATCH(R13,$A$2:$A$231,0))) -> Aisha Villanueva | T13: Standard | U13: =H13&" | "&G13 -> Commercial & Transactions | Lawyer - Mid
A14: VL-1018 | B14: Devin | C14: Okoro | D14: devin.okoro@vandelay.example | E14: Attorney | F14: L5 | G14: Lawyer - Junior | H14: Commercial & Transactions | J14: New York | K14: United States | L14: Americas - US | M14: HQ | N14: Office | O14: 39388 | P14: =ROUND((About!$B$3-O14)/365.25,1) -> 18.9 | Q14: =IF(O14>About!$B$4,"Yes","No") -> No | R14: VL-1002 | S14: =IF(R14="","",INDEX($B$2:$B$231,MATCH(R14,$A$2:$A$231,0))&" "&INDEX($C$2:$C$231,MATCH(R14,$A$2:$A$231,0))) -> Aisha Villanueva | T14: Standard | U14: =H14&" | "&G14 -> Commercial & Transactions | Lawyer - Junior
A15: VL-1019 | B15: Miles | C15: Castillo | D15: miles.castillo@vandelay.example | E15: Counsel | F15: L4 | G15: Lawyer - Mid | H15: Commercial & Transactions | J15: New York | K15: United States | L15: Americas - US | M15: HQ | N15: Office | O15: 42079 | P15: =ROUND((About!$B$3-O15)/365.25,1) -> 11.5 | Q15: =IF(O15>About!$B$4,"Yes","No") -> No | R15: VL-1002 | S15: =IF(R15="","",INDEX($B$2:$B$231,MATCH(R15,$A$2:$A$231,0))&" "&INDEX($C$2:$C$231,MATCH(R15,$A$2:$A$231,0))) -> Aisha Villanueva | T15: Standard | U15: =H15&" | "&G15 -> Commercial & Transactions | Lawyer - Mid
A16: VL-1020 | B16: Miles | C16: Wentworth | D16: miles.wentworth@vandelay.example | E16: Attorney | F16: L5 | G16: Lawyer - Junior | H16: Commercial & Transactions | J16: Chicago | K16: United States | L16: Americas - US | M16: Regional office | N16: Hybrid | O16: 46096 | P16: =ROUND((About!$B$3-O16)/365.25,1) -> 0.5 | Q16: =IF(O16>About!$B$4,"Yes","No") -> Yes | R16: VL-1002 | S16: =IF(R16="","",INDEX($B$2:$B$231,MATCH(R16,$A$2:$A$231,0))&" "&INDEX($C$2:$C$231,MATCH(R16,$A$2:$A$231,0))) -> Aisha Villanueva | T16: Standard | U16: =H16&" | "&G16 -> Commercial & Transactions | Lawyer - Junior
... A36: VL-1040 | B36: Cormac | C36: Abubakar | D36: cormac.abubakar@vandelay.example | E36: Attorney | F36: L5 | G36: Lawyer - Junior | H36: Commercial & Transactions | J36: New York | K36: United States | L36: Americas - US | M36: HQ | N36: Hybrid | O36: 38780 | P36: =ROUND((About!$B$3-O36)/365.25,1) -> 20.5 | Q36: =IF(O36>About!$B$4,"Yes","No") -> No | R36: VL-1002 | S36: =IF(R36="","",INDEX($B$2:$B$231,MATCH(R36,$A$2:$A$231,0))&" "&INDEX($C$2:$C$231,MATCH(R36,$A$2:$A$231,0))) -> Aisha Villanueva | T36: Standard | U36: =H36&" | "&G36 -> Commercial & Transactions | Lawyer - Junior
A37: VL-1150 | B37: Yara | C37: Oduya | D37: yara.oduya@vandelay.example | E37: Paralegal | F37: P2 | G37: Paraprofessional | H37: Commercial & Transactions | I37: Paralegals | J37: New York | K37: United States | L37: Americas - US | M37: HQ | N37: Hybrid | O37: 45192 | P37: =ROUND((About!$B$3-O37)/365.25,1) -> 3 | Q37: =IF(O37>About!$B$4,"Yes","No") -> No | R37: VL-1136 | S37: =IF(R37="","",INDEX($B$2:$B$231,MATCH(R37,$A$2:$A$231,0))&" "&INDEX($C$2:$C$231,MATCH(R37,$A$2:$A$231,0))) -> Ada Paredes | T37: Standard | U37: =H37&" | "&G37 -> Commercial & Transactions | Paraprofessional
A38: VL-1151 | B38: Kavya | C38: Sinclair | D38: kavya.sinclair@vandelay.example | E38: Paralegal | F38: P2 | G38: Paraprofessional | H38: Commercial & Transactions | I38: Paralegals | J38: Washington, DC | K38: United States | L38: Americas - US | M38: Regional office | N38: Office | O38: 40963 | P38: =ROUND((About!$B$3-O38)/365.25,1) -> 14.5 | Q38: =IF(O38>About!$B$4,"Yes","No") -> No | R38: VL-1136 | S38: =IF(R38="","",INDEX($B$2:$B$231,MATCH(R38,$A$2:$A$231,0))&" "&INDEX($C$2:$C$231,MATCH(R38,$A$2:$A$231,0))) -> Ada Paredes | T38: Standard | U38: =H38&" | "&G38 -> Commercial & Transactions | Paraprofessional
A39: VL-1152 | B39: Ingrid | C39: Larsson | D39: ingrid.larsson@vandelay.example | E39: Paralegal | F39: P2 | G39: Paraprofessional | H39: Commercial & Transactions | I39: Paralegals | J39: Chicago | K39: United States | L39: Americas - US | M39: Regional office | N39: Hybrid | O39: 43237 | P39: =ROUND((About!$B$3-O39)/365.25,1) -> 8.3 | Q39: =IF(O39>About!$B$4,"Yes","No") -> No | R39: VL-1136 | S39: =IF(R39="","",INDEX($B$2:$B$231,MATCH(R39,$A$2:$A$231,0))&" "&INDEX($C$2:$C$231,MATCH(R39,$A$2:$A$231,0))) -> Ada Paredes | T39: Standard | U39: =H39&" | "&G39 -> Commercial & Transactions | Paraprofessional
A40: VL-1153 | B40: Maya | C40: Adler | D40: maya.adler@vandelay.example | E40: Paralegal | F40: P2 | G40: Paraprofessional | H40: Commercial & Transactions | I40: Paralegals | J40: Chicago | K40: United States | L40: Americas - US | M40: Regional office | N40: Hybrid | O40: 46018 | P40: =ROUND((About!$B$3-O40)/365.25,1) -> 0.7 | Q40: =IF(O40>About!$B$4,"Yes","No") -> Yes | R40: VL-1136 | S40: =IF(R40="","",INDEX($B$2:$B$231,MATCH(R40,$A$2:$A$231,0))&" "&INDEX($C$2:$C$231,MATCH(R40,$A$2:$A$231,0))) -> Ada Paredes | T40: Standard | U40: =H40&" | "&G40 -> Commercial & Transactions | Paraprofessional
A41: VL-1154 | B41: Declan | C41: Hargreaves | D41: declan.hargreaves@vandelay.example | E41: Paralegal | F41: P2 | G41: Paraprofessional | H41: Commercial & Transactions | I41: Paralegals | J41: London | K41: United Kingdom | L41: EMEA | M41: International office | N41: Hybrid | O41: 41726 | P41: =ROUND((About!$B$3-O41)/365.25,1) -> 12.5 | Q41: =IF(O41>About!$B$4,"Yes","No") -> No | R41: VL-1136 | S41: =IF(R41="","",INDEX($B$2:$B$231,MATCH(R41,$A$2:$A$231,0))&" "&INDEX($C$2:$C$231,MATCH(R41,$A$2:$A$231,0))) -> Ada Paredes | T41: Standard | U41: =H41&" | "&G41 -> Commercial & Transactions | Paraprofessional
A42: VL-1164 | B42: Daniel | C42: Ellison | D42: daniel.ellison@vandelay.example | E42: Contracts Manager | F42: P1 | G42: Paraprofessional - Lead | H42: Commercial & Transactions | I42: Contracts | J42: New York | K42: United States | L42: Americas - US | M42: HQ | N42: Hybrid | O42: 43046 | P42: =ROUND((About!$B$3-O42)/365.25,1) -> 8.8 | Q42: =IF(O42>About!$B$4,"Yes","No") -> No | R42: VL-1002 | S42: =IF(R42="","",INDEX($B$2:$B$231,MATCH(R42,$A$2:$A$231,0))&" "&INDEX($C$2:$C$231,MATCH(R42,$A$2:$A$231,0))) -> Aisha Villanueva | T42: Standard | U42: =H42&" | "&G42 -> Commercial & Transactions | Paraprofessional - Lead
A43: VL-1165 | B43: Marcus | C43: Navarro | D43: marcus.navarro@vandelay.example | E43: Senior Contract Analyst | F43: P2 | G43: Paraprofessional | H43: Commercial & Transactions | I43: Contracts | J43: New York | K43: United States | L43: Americas - US | M43: HQ | N43: Office | O43: 43760 | P43: =ROUND((About!$B$3-O43)/365.25,1) -> 6.9 | Q43: =IF(O43>About!$B$4,"Yes","No") -> No | R43: VL-1164 | S43: =IF(R43="","",INDEX($B$2:$B$231,MATCH(R43,$A$2:$A$231,0))&" "&INDEX($C$2:$C$231,MATCH(R43,$A$2:$A$231,0))) -> Daniel Ellison | T43: Standard | U43: =H43&" | "&G43 -> Commercial & Transactions | Paraprofessional
A44: VL-1166 | B44: Mei | C44: Rasmussen | D44: mei.rasmussen@vandelay.example | E44: Senior Contract Analyst | F44: P2 | G44: Paraprofessional | H44: Commercial & Transactions | I44: Contracts | J44: Atlanta | K44: United States | L44: Americas - US | M44: Regional office | N44: Hybrid | O44: 41605 | P44: =ROUND((About!$B$3-O44)/365.25,1) -> 12.8 | Q44: =IF(O44>About!$B$4,"Yes","No") -> No | R44: VL-1164 | S44: =IF(R44="","",INDEX($B$2:$B$231,MATCH(R44,$A$2:$A$231,0))&" "&INDEX($C$2:$C$231,MATCH(R44,$A$2:$A$231,0))) -> Daniel Ellison | T44: Standard | U44: =H44&" | "&G44 -> Commercial & Transactions | Paraprofessional
A45: VL-1167 | B45: Leo | C45: Mbeki | D45: leo.mbeki@vandelay.example | E45: Senior Contract Analyst | F45: P2 | G45: Paraprofessional | H45: Commercial & Transactions | I45: Contracts | J45: Chicago | K45: United States | L45: Americas - US | M45: Regional office | N45: Remote | O45: 45673 | P45: =ROUND((About!$B$3-O45)/365.25,1) -> 1.6 | Q45: =IF(O45>About!$B$4,"Yes","No") -> Yes | R45: VL-1164 | S45: =IF(R45="","",INDEX($B$2:$B$231,MATCH(R45,$A$2:$A$231,0))&" "&INDEX($C$2:$C$231,MATCH(R45,$A$2:$A$231,0))) -> Daniel Ellison | T45: Standard | U45: =H45&" | "&G45 -> Commercial & Transactions | Paraprofessional
A46: VL-1168 | B46: Benedict | C46: Fairbanks | D46: benedict.fairbanks@vandelay.example | E46: Senior Contract Analyst | F46: P2 | G46: Paraprofessional | H46: Commercial & Transactions | I46: Contracts | J46: New York | K46: United States | L46: Americas - US | M46: HQ | N46: Hybrid | O46: 44537 | P46: =ROUND((About!$B$3-O46)/365.25,1) -> 4.8 | Q46: =IF(O46>About!$B$4,"Yes","No") -> No | R46: VL-1164 | S46: =IF(R46="","",INDEX($B$2:$B$231,MATCH(R46,$A$2:$A$231,0))&" "&INDEX($C$2:$C$231,MATCH(R46,$A$2:$A$231,0))) -> Daniel Ellison | T46: Standard | U46: =H46&" | "&G46 -> Commercial & Transactions | Paraprofessional
A47: VL-1169 | B47: Marcel | C47: Obi | D47: marcel.obi@vandelay.example | E47: Contract Analyst | F47: P2 | G47: Paraprofessional | H47: Commercial & Transactions | I47: Contracts | J47: New York | K47: United States | L47: Americas - US | M47: HQ | N47: Office | O47: 44766 | P47: =ROUND((About!$B$3-O47)/365.25,1) -> 4.1 | Q47: =IF(O47>About!$B$4,"Yes","No") -> No | R47: VL-1164 | S47: =IF(R47="","",INDEX($B$2:$B$231,MATCH(R47,$A$2:$A$231,0))&" "&INDEX($C$2:$C$231,MATCH(R47,$A$2:$A$231,0))) -> Daniel Ellison | T47: Standard | U47: =H47&" | "&G47 -> Commercial & Transactions | Paraprofessional
A48: VL-1170 | B48: Kenji | C48: Achebe | D48: kenji.achebe@vandelay.example | E48: Contract Analyst | F48: P2 | G48: Paraprofessional | H48: Commercial & Transactions | I48: Contracts | J48: New York | K48: United States | L48: Americas - US | M48: HQ | N48: Hybrid | O48: 45183 | P48: =ROUND((About!$B$3-O48)/365.25,1) -> 3 | Q48: =IF(O48>About!$B$4,"Yes","No") -> No | R48: VL-1164 | S48: =IF(R48="","",INDEX($B$2:$B$231,MATCH(R48,$A$2:$A$231,0))&" "&INDEX($C$2:$C$231,MATCH(R48,$A$2:$A$231,0))) -> Daniel Ellison | T48: Standard | U48: =H48&" | "&G48 -> Commercial & Transactions | Paraprofessional
... A57: VL-1230 | B57: Daniel | C57: Carvalho | D57: daniel.carvalho@vandelay.example | E57: Executive Assistant | F57: EA | G57: Executive Assistant | H57: Commercial & Transactions | I57: Executive Support | J57: New York | K57: United States | L57: Americas - US | M57: HQ | N57: Hybrid | O57: 42820 | P57: =ROUND((About!$B$3-O57)/365.25,1) -> 9.5 | Q57: =IF(O57>About!$B$4,"Yes","No") -> No | R57: VL-1002 | S57: =IF(R57="","",INDEX($B$2:$B$231,MATCH(R57,$A$2:$A$231,0))&" "&INDEX($C$2:$C$231,MATCH(R57,$A$2:$A$231,0))) -> Aisha Villanueva | T57: Standard | U57: =H57&" | "&G57 -> Commercial & Transactions | Executive Assistant
A58: VL-1003 | B58: Ines | C58: Duarte | D58: ines.duarte@vandelay.example | E58: Deputy General Counsel, Litigation & Disputes | F58: L2 | G58: Lawyer - Leadership | H58: Litigation & Disputes | J58: New York | K58: United States | L58: Americas - US | M58: HQ | N58: Office | O58: 41039 | P58: =ROUND((About!$B$3-O58)/365.25,1) -> 14.3 | Q58: =IF(O58>About!$B$4,"Yes","No") -> No | R58: VL-1001 | S58: =IF(R58="","",INDEX($B$2:$B$231,MATCH(R58,$A$2:$A$231,0))&" "&INDEX($C$2:$C$231,MATCH(R58,$A$2:$A$231,0))) -> Simon Rasmussen | T58: Standard | U58: =H58&" | "&G58 -> Litigation & Disputes | Lawyer - Leadership
A59: VL-1041 | B59: Reuben | C59: Okonkwo | D59: reuben.okonkwo@vandelay.example | E59: Attorney | F59: L5 | G59: Lawyer - Junior | H59: Litigation & Disputes | J59: New York | K59: United States | L59: Americas - US | M59: HQ | N59: Hybrid | O59: 45810 | P59: =ROUND((About!$B$3-O59)/365.25,1) -> 1.3 | Q59: =IF(O59>About!$B$4,"Yes","No") -> Yes | R59: VL-1003 | S59: =IF(R59="","",INDEX($B$2:$B$231,MATCH(R59,$A$2:$A$231,0))&" "&INDEX($C$2:$C$231,MATCH(R59,$A$2:$A$231,0))) -> Ines Duarte | T59: Standard | U59: =H59&" | "&G59 -> Litigation & Disputes | Lawyer - Junior
A60: VL-1042 | B60: Ezra | C60: Molnar | D60: ezra.molnar@vandelay.example | E60: Counsel | F60: L4 | G60: Lawyer - Mid | H60: Litigation & Disputes | J60: New York | K60: United States | L60: Americas - US | M60: HQ | N60: Office | O60: 43493 | P60: =ROUND((About!$B$3-O60)/365.25,1) -> 7.6 | Q60: =IF(O60>About!$B$4,"Yes","No") -> No | R60: VL-1003 | S60: =IF(R60="","",INDEX($B$2:$B$231,MATCH(R60,$A$2:$A$231,0))&" "&INDEX($C$2:$C$231,MATCH(R60,$A$2:$A$231,0))) -> Ines Duarte | T60: Standard | U60: =H60&" | "&G60 -> Litigation & Disputes | Lawyer - Mid
A61: VL-1043 | B61: Idris | C61: Kessler | D61: idris.kessler@vandelay.example | E61: Senior Counsel | F61: L3 | G61: Lawyer - Senior | H61: Litigation & Disputes | J61: New York | K61: United States | L61: Americas - US | M61: HQ | N61: Remote | O61: 40513 | P61: =ROUND((About!$B$3-O61)/365.25,1) -> 15.8 | Q61: =IF(O61>About!$B$4,"Yes","No") -> No | R61: VL-1003 | S61: =IF(R61="","",INDEX($B$2:$B$231,MATCH(R61,$A$2:$A$231,0))&" "&INDEX($C$2:$C$231,MATCH(R61,$A$2:$A$231,0))) -> Ines Duarte | T61: Standard | U61: =H61&" | "&G61 -> Litigation & Disputes | Lawyer - Senior
A62: VL-1044 | B62: Imani | C62: Ndlovu | D62: imani.ndlovu@vandelay.example | E62: Counsel | F62: L4 | G62: Lawyer - Mid | H62: Litigation & Disputes | J62: New York | K62: United States | L62: Americas - US | M62: HQ | N62: Hybrid | O62: 43976 | P62: =ROUND((About!$B$3-O62)/365.25,1) -> 6.3 | Q62: =IF(O62>About!$B$4,"Yes","No") -> No | R62: VL-1003 | S62: =IF(R62="","",INDEX($B$2:$B$231,MATCH(R62,$A$2:$A$231,0))&" "&INDEX($C$2:$C$231,MATCH(R62,$A$2:$A$231,0))) -> Ines Duarte | T62: Standard | U62: =H62&" | "&G62 -> Litigation & Disputes | Lawyer - Mid
A63: VL-1045 | B63: Renata | C63: Beaumont | D63: renata.beaumont@vandelay.example | E63: Senior Counsel | F63: L3 | G63: Lawyer - Senior | H63: Litigation & Disputes | J63: Houston | K63: United States | L63: Americas - US | M63: Regional office | N63: Office | O63: 43711 | P63: =ROUND((About!$B$3-O63)/365.25,1) -> 7 | Q63: =IF(O63>About!$B$4,"Yes","No") -> No | R63: VL-1003 | S63: =IF(R63="","",INDEX($B$2:$B$231,MATCH(R63,$A$2:$A$231,0))&" "&INDEX($C$2:$C$231,MATCH(R63,$A$2:$A$231,0))) -> Ines Duarte | T63: Standard | U63: =H63&" | "&G63 -> Litigation & Disputes | Lawyer - Senior
A64: VL-1046 | B64: Renata | C64: Aguilar | D64: renata.aguilar@vandelay.example | E64: Attorney | F64: L5 | G64: Lawyer - Junior | H64: Litigation & Disputes | J64: Chicago | K64: United States | L64: Americas - US | M64: Regional office | N64: Remote | O64: 45571 | P64: =ROUND((About!$B$3-O64)/365.25,1) -> 1.9 | Q64: =IF(O64>About!$B$4,"Yes","No") -> Yes | R64: VL-1003 | S64: =IF(R64="","",INDEX($B$2:$B$231,MATCH(R64,$A$2:$A$231,0))&" "&INDEX($C$2:$C$231,MATCH(R64,$A$2:$A$231,0))) -> Ines Duarte | T64: Standard | U64: =H64&" | "&G64 -> Litigation & Disputes | Lawyer - Junior
A65: VL-1047 | B65: Caleb | C65: Espinoza | D65: caleb.espinoza@vandelay.example | E65: Counsel | F65: L4 | G65: Lawyer - Mid | H65: Litigation & Disputes | J65: New York | K65: United States | L65: Americas - US | M65: HQ | N65: Office | O65: 45854 | P65: =ROUND((About!$B$3-O65)/365.25,1) -> 1.1 | Q65: =IF(O65>About!$B$4,"Yes","No") -> Yes | R65: VL-1003 | S65: =IF(R65="","",INDEX($B$2:$B$231,MATCH(R65,$A$2:$A$231,0))&" "&INDEX($C$2:$C$231,MATCH(R65,$A$2:$A$231,0))) -> Ines Duarte | T65: Standard | U65: =H65&" | "&G65 -> Litigation & Disputes | Lawyer - Mid
A66: VL-1048 | B66: Emmett | C66: Gallagher | D66: emmett.gallagher@vandelay.example | E66: Counsel | F66: L4 | G66: Lawyer - Mid | H66: Litigation & Disputes | J66: New York | K66: United States | L66: Americas - US | M66: HQ | N66: Office | O66: 43613 | P66: =ROUND((About!$B$3-O66)/365.25,1) -> 7.3 | Q66: =IF(O66>About!$B$4,"Yes","No") -> No | R66: VL-1003 | S66: =IF(R66="","",INDEX($B$2:$B$231,MATCH(R66,$A$2:$A$231,0))&" "&INDEX($C$2:$C$231,MATCH(R66,$A$2:$A$231,0))) -> Ines Duarte | T66: Standard | U66: =H66&" | "&G66 -> Litigation & Disputes | Lawyer - Mid
A67: VL-1049 | B67: Sienna | C67: Mensah | D67: sienna.mensah@vandelay.example | E67: Counsel | F67: L4 | G67: Lawyer - Mid | H67: Litigation & Disputes | J67: New York | K67: United States | L67: Americas - US | M67: HQ | N67: Office | O67: 45316 | P67: =ROUND((About!$B$3-O67)/365.25,1) -> 2.6 | Q67: =IF(O67>About!$B$4,"Yes","No") -> No | R67: VL-1003 | S67: =IF(R67="","",INDEX($B$2:$B$231,MATCH(R67,$A$2:$A$231,0))&" "&INDEX($C$2:$C$231,MATCH(R67,$A$2:$A$231,0))) -> Ines Duarte | T67: Standard | U67: =H67&" | "&G67 -> Litigation & Disputes | Lawyer - Mid
...

Sheet Taxonomy
A1: Practice groups | B1: Budgeted lawyer headcount FY2026 (incl. lead) | C1: Actual: lawyers | D1: Actual: all staff | E1: Notes
A2: Office of the General Counsel | B2: 1 | C2: =COUNTIFS(Roster!$H:$H,A2,Roster!$F:$F,"L*") -> 1 | D2: =COUNTIF(Roster!$H:$H,A2) -> 3
A3: Commercial & Transactions | B3: 32 | C3: =COUNTIFS(Roster!$H:$H,A3,Roster!$F:$F,"L*") -> 32 | D3: =COUNTIF(Roster!$H:$H,A3) -> 53 | E3: Largest group. Houses the Contracts team (paraprofessional).
A4: Litigation & Disputes | B4: 26 | C4: =COUNTIFS(Roster!$H:$H,A4,Roster!$F:$F,"L*") -> 26 | D4: =COUNTIF(Roster!$H:$H,A4) -> 49 | E4: Houses Paralegals and Litigation Support & eDiscovery. Heaviest DMS users.
A5: Regulatory & Trade Compliance | B5: 16 | C5: =COUNTIFS(Roster!$H:$H,A5,Roster!$F:$F,"L*") -> 16 | D5: =COUNTIF(Roster!$H:$H,A5) -> 23 | E5: Import/export company: trade, customs, sanctions. Lead sits in Washington, DC. Staff in Singapore and Mexico City.
A6: Employment & Labor | B6: 14 | C6: =COUNTIFS(Roster!$H:$H,A6,Roster!$F:$F,"L*") -> 14 | D6: =COUNTIF(Roster!$H:$H,A6) -> 18
A7: Intellectual Property | B7: 12 | C7: =COUNTIFS(Roster!$H:$H,A7,Roster!$F:$F,"L*") -> 12 | D7: =COUNTIF(Roster!$H:$H,A7) -> 16
A8: Privacy & Data Protection | B8: 12 | C8: =COUNTIFS(Roster!$H:$H,A8,Roster!$F:$F,"L*") -> 12 | D8: =COUNTIF(Roster!$H:$H,A8) -> 13 | E8: Lead sits in London. Staff in London and Dublin.
A9: Corporate, Securities & Governance | B9: 12 | C9: =COUNTIFS(Roster!$H:$H,A9,Roster!$F:$F,"L*") -> 12 | D9: =COUNTIF(Roster!$H:$H,A9) -> 16
A10: Real Estate, Environmental & Safety | B10: 10 | C10: =COUNTIFS(Roster!$H:$H,A10,Roster!$F:$F,"L*") -> 10 | D10: =COUNTIF(Roster!$H:$H,A10) -> 13
A11: Legal Operations | B11: 0 | C11: =COUNTIFS(Roster!$H:$H,A11,Roster!$F:$F,"L*") -> 0 | D11: =COUNTIF(Roster!$H:$H,A11) -> 26 | E11: Legal Operations, Legal Technology (incl. DMS Administrators), Records & IG, Vendor Management & e-Billing, Knowledge, Training & Enablement.
A13: Level codes | B13: Title(s) | C13: Level band | D13: Cohort use
A14: L1 | B14: General Counsel | C14: Lawyer - Leadership | D14: Cohort key = practice_group | level_band. Survey responses are anonymous and reported at cohort level; telemetry and training are per employee_id and roll up to the same cohorts.
A15: L2 | B15: Deputy General Counsel (practice lead) | C15: Lawyer - Leadership
A16: L3 | B16: Senior Counsel | C16: Lawyer - Senior
A17: L4 | B17: Counsel | C17: Lawyer - Mid
A18: L5 | B18: Attorney | C18: Lawyer - Junior
A19: P1 | B19: Paralegal Manager, Contracts Manager | C19: Paraprofessional - Lead
A20: P2 | B20: Paralegal, Contract Analyst, Litigation Support, eDiscovery, IP Docketing, Compliance Analyst | C20: Paraprofessional
A21: O1 | B21: Director / Managers in Legal Operations, Legal Technology, Records & IG | C21: Legal Ops - Leadership
A22: O2 | B22: Analysts, DMS Administrators, Records Specialists, Knowledge Manager, Training & Enablement Lead | C22: Legal Ops - Staff
A23: EA | B23: Executive Assistant | C23: Executive Assistant
A25: Locations | B25: Country | C25: Region | D25: Office type | E25: Actual headcount
A26: New York | B26: United States | C26: Americas - US | D26: HQ | E26: =COUNTIF(Roster!$J:$J,A26) -> 131
A27: Chicago | B27: United States | C27: Americas - US | D27: Regional office | E27: =COUNTIF(Roster!$J:$J,A27) -> 21
A28: Houston | B28: United States | C28: Americas - US | D28: Regional office | E28: =COUNTIF(Roster!$J:$J,A28) -> 13
A29: Washington, DC | B29: United States | C29: Americas - US | D29: Regional office | E29: =COUNTIF(Roster!$J:$J,A29) -> 13
A30: San Francisco | B30: United States | C30: Americas - US | D30: Regional office | E30: =COUNTIF(Roster!$J:$J,A30) -> 15
A31: Atlanta | B31: United States | C31: Americas - US | D31: Regional office | E31: =COUNTIF(Roster!$J:$J,A31) -> 8
A32: Los Angeles | B32: United States | C32: Americas - US | D32: Regional office | E32: =COUNTIF(Roster!$J:$J,A32) -> 4
A33: London | B33: United Kingdom | C33: EMEA | D33: International office | E33: =COUNTIF(Roster!$J:$J,A33) -> 12
A34: Dublin | B34: Ireland | C34: EMEA | D34: International office | E34: =COUNTIF(Roster!$J:$J,A34) -> 5
A35: Singapore | B35: Singapore | C35: APAC | D35: International office | E35: =COUNTIF(Roster!$J:$J,A35) -> 5
A36: Mexico City | B36: Mexico | C36: LATAM | D36: International office | E36: =COUNTIF(Roster!$J:$J,A36) -> 3

Sheet Summary
A1: Headcount by practice group and level band | B1: Lawyer - Leadership | C1: Lawyer - Senior | D1: Lawyer - Mid | E1: Lawyer - Junior | F1: Paraprofessional - Lead | G1: Paraprofessional | H1: Legal Ops - Leadership | I1: Legal Ops - Staff | J1: Executive Assistant | K1: Total
A2: Office of the General Counsel | B2: =COUNTIFS(Roster!$H:$H,$A2,Roster!$G:$G,B$1) -> 1 | C2: =COUNTIFS(Roster!$H:$H,$A2,Roster!$G:$G,C$1) -> 0 | D2: =COUNTIFS(Roster!$H:$H,$A2,Roster!$G:$G,D$1) -> 0 | E2: =COUNTIFS(Roster!$H:$H,$A2,Roster!$G:$G,E$1) -> 0 | F2: =COUNTIFS(Roster!$H:$H,$A2,Roster!$G:$G,F$1) -> 0 | G2: =COUNTIFS(Roster!$H:$H,$A2,Roster!$G:$G,G$1) -> 0 | H2: =COUNTIFS(Roster!$H:$H,$A2,Roster!$G:$G,H$1) -> 0 | I2: =COUNTIFS(Roster!$H:$H,$A2,Roster!$G:$G,I$1) -> 0 | J2: =COUNTIFS(Roster!$H:$H,$A2,Roster!$G:$G,J$1) -> 2 | K2: =SUM(B2:J2) -> 3
A3: Commercial & Transactions | B3: =COUNTIFS(Roster!$H:$H,$A3,Roster!$G:$G,B$1) -> 1 | C3: =COUNTIFS(Roster!$H:$H,$A3,Roster!$G:$G,C$1) -> 7 | D3: =COUNTIFS(Roster!$H:$H,$A3,Roster!$G:$G,D$1) -> 13 | E3: =COUNTIFS(Roster!$H:$H,$A3,Roster!$G:$G,E$1) -> 11 | F3: =COUNTIFS(Roster!$H:$H,$A3,Roster!$G:$G,F$1) -> 1 | G3: =COUNTIFS(Roster!$H:$H,$A3,Roster!$G:$G,G$1) -> 17 | H3: =COUNTIFS(Roster!$H:$H,$A3,Roster!$G:$G,H$1) -> 0 | I3: =COUNTIFS(Roster!$H:$H,$A3,Roster!$G:$G,I$1) -> 0 | J3: =COUNTIFS(Roster!$H:$H,$A3,Roster!$G:$G,J$1) -> 3 | K3: =SUM(B3:J3) -> 53
A4: Litigation & Disputes | B4: =COUNTIFS(Roster!$H:$H,$A4,Roster!$G:$G,B$1) -> 1 | C4: =COUNTIFS(Roster!$H:$H,$A4,Roster!$G:$G,C$1) -> 6 | D4: =COUNTIFS(Roster!$H:$H,$A4,Roster!$G:$G,D$1) -> 10 | E4: =COUNTIFS(Roster!$H:$H,$A4,Roster!$G:$G,E$1) -> 9 | F4: =COUNTIFS(Roster!$H:$H,$A4,Roster!$G:$G,F$1) -> 1 | G4: =COUNTIFS(Roster!$H:$H,$A4,Roster!$G:$G,G$1) -> 19 | H4: =COUNTIFS(Roster!$H:$H,$A4,Roster!$G:$G,H$1) -> 0 | I4: =COUNTIFS(Roster!$H:$H,$A4,Roster!$G:$G,I$1) -> 0 | J4: =COUNTIFS(Roster!$H:$H,$A4,Roster!$G:$G,J$1) -> 3 | K4: =SUM(B4:J4) -> 49
A5: Regulatory & Trade Compliance | B5: =COUNTIFS(Roster!$H:$H,$A5,Roster!$G:$G,B$1) -> 1 | C5: =COUNTIFS(Roster!$H:$H,$A5,Roster!$G:$G,C$1) -> 3 | D5: =COUNTIFS(Roster!$H:$H,$A5,Roster!$G:$G,D$1) -> 7 | E5: =COUNTIFS(Roster!$H:$H,$A5,Roster!$G:$G,E$1) -> 5 | F5: =COUNTIFS(Roster!$H:$H,$A5,Roster!$G:$G,F$1) -> 0 | G5: =COUNTIFS(Roster!$H:$H,$A5,Roster!$G:$G,G$1) -> 6 | H5: =COUNTIFS(Roster!$H:$H,$A5,Roster!$G:$G,H$1) -> 0 | I5: =COUNTIFS(Roster!$H:$H,$A5,Roster!$G:$G,I$1) -> 0 | J5: =COUNTIFS(Roster!$H:$H,$A5,Roster!$G:$G,J$1) -> 1 | K5: =SUM(B5:J5) -> 23
A6: Employment & Labor | B6: =COUNTIFS(Roster!$H:$H,$A6,Roster!$G:$G,B$1) -> 1 | C6: =COUNTIFS(Roster!$H:$H,$A6,Roster!$G:$G,C$1) -> 3 | D6: =COUNTIFS(Roster!$H:$H,$A6,Roster!$G:$G,D$1) -> 5 | E6: =COUNTIFS(Roster!$H:$H,$A6,Roster!$G:$G,E$1) -> 5 | F6: =COUNTIFS(Roster!$H:$H,$A6,Roster!$G:$G,F$1) -> 0 | G6: =COUNTIFS(Roster!$H:$H,$A6,Roster!$G:$G,G$1) -> 3 | H6: =COUNTIFS(Roster!$H:$H,$A6,Roster!$G:$G,H$1) -> 0 | I6: =COUNTIFS(Roster!$H:$H,$A6,Roster!$G:$G,I$1) -> 0 | J6: =COUNTIFS(Roster!$H:$H,$A6,Roster!$G:$G,J$1) -> 1 | K6: =SUM(B6:J6) -> 18
A7: Intellectual Property | B7: =COUNTIFS(Roster!$H:$H,$A7,Roster!$G:$G,B$1) -> 1 | C7: =COUNTIFS(Roster!$H:$H,$A7,Roster!$G:$G,C$1) -> 2 | D7: =COUNTIFS(Roster!$H:$H,$A7,Roster!$G:$G,D$1) -> 5 | E7: =COUNTIFS(Roster!$H:$H,$A7,Roster!$G:$G,E$1) -> 4 | F7: =COUNTIFS(Roster!$H:$H,$A7,Roster!$G:$G,F$1) -> 0 | G7: =COUNTIFS(Roster!$H:$H,$A7,Roster!$G:$G,G$1) -> 3 | H7: =COUNTIFS(Roster!$H:$H,$A7,Roster!$G:$G,H$1) -> 0 | I7: =COUNTIFS(Roster!$H:$H,$A7,Roster!$G:$G,I$1) -> 0 | J7: =COUNTIFS(Roster!$H:$H,$A7,Roster!$G:$G,J$1) -> 1 | K7: =SUM(B7:J7) -> 16
A8: Privacy & Data Protection | B8: =COUNTIFS(Roster!$H:$H,$A8,Roster!$G:$G,B$1) -> 1 | C8: =COUNTIFS(Roster!$H:$H,$A8,Roster!$G:$G,C$1) -> 2 | D8: =COUNTIFS(Roster!$H:$H,$A8,Roster!$G:$G,D$1) -> 5 | E8: =COUNTIFS(Roster!$H:$H,$A8,Roster!$G:$G,E$1) -> 4 | F8: =COUNTIFS(Roster!$H:$H,$A8,Roster!$G:$G,F$1) -> 0 | G8: =COUNTIFS(Roster!$H:$H,$A8,Roster!$G:$G,G$1) -> 0 | H8: =COUNTIFS(Roster!$H:$H,$A8,Roster!$G:$G,H$1) -> 0 | I8: =COUNTIFS(Roster!$H:$H,$A8,Roster!$G:$G,I$1) -> 0 | J8: =COUNTIFS(Roster!$H:$H,$A8,Roster!$G:$G,J$1) -> 1 | K8: =SUM(B8:J8) -> 13
A9: Corporate, Securities & Governance | B9: =COUNTIFS(Roster!$H:$H,$A9,Roster!$G:$G,B$1) -> 1 | C9: =COUNTIFS(Roster!$H:$H,$A9,Roster!$G:$G,C$1) -> 2 | D9: =COUNTIFS(Roster!$H:$H,$A9,Roster!$G:$G,D$1) -> 5 | E9: =COUNTIFS(Roster!$H:$H,$A9,Roster!$G:$G,E$1) -> 4 | F9: =COUNTIFS(Roster!$H:$H,$A9,Roster!$G:$G,F$1) -> 0 | G9: =COUNTIFS(Roster!$H:$H,$A9,Roster!$G:$G,G$1) -> 3 | H9: =COUNTIFS(Roster!$H:$H,$A9,Roster!$G:$G,H$1) -> 0 | I9: =COUNTIFS(Roster!$H:$H,$A9,Roster!$G:$G,I$1) -> 0 | J9: =COUNTIFS(Roster!$H:$H,$A9,Roster!$G:$G,J$1) -> 1 | K9: =SUM(B9:J9) -> 16
A10: Real Estate, Environmental & Safety | B10: =COUNTIFS(Roster!$H:$H,$A10,Roster!$G:$G,B$1) -> 1 | C10: =COUNTIFS(Roster!$H:$H,$A10,Roster!$G:$G,C$1) -> 2 | D10: =COUNTIFS(Roster!$H:$H,$A10,Roster!$G:$G,D$1) -> 4 | E10: =COUNTIFS(Roster!$H:$H,$A10,Roster!$G:$G,E$1) -> 3 | F10: =COUNTIFS(Roster!$H:$H,$A10,Roster!$G:$G,F$1) -> 0 | G10: =COUNTIFS(Roster!$H:$H,$A10,Roster!$G:$G,G$1) -> 2 | H10: =COUNTIFS(Roster!$H:$H,$A10,Roster!$G:$G,H$1) -> 0 | I10: =COUNTIFS(Roster!$H:$H,$A10,Roster!$G:$G,I$1) -> 0 | J10: =COUNTIFS(Roster!$H:$H,$A10,Roster!$G:$G,J$1) -> 1 | K10: =SUM(B10:J10) -> 13
A11: Legal Operations | B11: =COUNTIFS(Roster!$H:$H,$A11,Roster!$G:$G,B$1) -> 0 | C11: =COUNTIFS(Roster!$H:$H,$A11,Roster!$G:$G,C$1) -> 0 | D11: =COUNTIFS(Roster!$H:$H,$A11,Roster!$G:$G,D$1) -> 0 | E11: =COUNTIFS(Roster!$H:$H,$A11,Roster!$G:$G,E$1) -> 0 | F11: =COUNTIFS(Roster!$H:$H,$A11,Roster!$G:$G,F$1) -> 0 | G11: =COUNTIFS(Roster!$H:$H,$A11,Roster!$G:$G,G$1) -> 0 | H11: =COUNTIFS(Roster!$H:$H,$A11,Roster!$G:$G,H$1) -> 6 | I11: =COUNTIFS(Roster!$H:$H,$A11,Roster!$G:$G,I$1) -> 19 | J11: =COUNTIFS(Roster!$H:$H,$A11,Roster!$G:$G,J$1) -> 1 | K11: =SUM(B11:J11) -> 26
A12: Total | B12: =SUM(B2:B11) -> 9 | C12: =SUM(C2:C11) -> 27 | D12: =SUM(D2:D11) -> 54 | E12: =SUM(E2:E11) -> 45 | F12: =SUM(F2:F11) -> 2 | G12: =SUM(G2:G11) -> 53 | H12: =SUM(H2:H11) -> 6 | I12: =SUM(I2:I11) -> 19 | ... K12: =SUM(K2:K11) -> 230
A14: Headcount by location
A15: New York | B15: =COUNTIF(Roster!$J:$J,A15) -> 131
A16: Chicago | B16: =COUNTIF(Roster!$J:$J,A16) -> 21
A17: Houston | B17: =COUNTIF(Roster!$J:$J,A17) -> 13
A18: Washington, DC | B18: =COUNTIF(Roster!$J:$J,A18) -> 13
A19: San Francisco | B19: =COUNTIF(Roster!$J:$J,A19) -> 15
A20: Atlanta | B20: =COUNTIF(Roster!$J:$J,A20) -> 8
A21: Los Angeles | B21: =COUNTIF(Roster!$J:$J,A21) -> 4
A22: London | B22: =COUNTIF(Roster!$J:$J,A22) -> 12
A23: Dublin | B23: =COUNTIF(Roster!$J:$J,A23) -> 5
A24: Singapore | B24: =COUNTIF(Roster!$J:$J,A24) -> 5
A25: Mexico City | B25: =COUNTIF(Roster!$J:$J,A25) -> 3
A26: Total | B26: =SUM(B15:B25) -> 230
A28: Headcount checks
A29: Total roster rows | B29: =COUNTA(Roster!$A:$A)-1 -> 230
A30: Approved headcount FY2026 | B30: 230
A31: Joined after DMS go-live | B31: =COUNTIF(Roster!$Q:$Q,"Yes") -> 63
A32: Share joined after go-live | B32: =B31/B29 -> 0.27391304
A33: Overseas headcount (EMEA + APAC + LATAM) | B33: =COUNTIF(Roster!$L:$L,"EMEA")+COUNTIF(Roster!$L:$L,"APAC")+COUNTIF(Roster!$L:$L,"LATAM") -> 25
A34: DMS Admin role holders | B34: =COUNTIF(Roster!$T:$T,"Admin") -> 4

Sheet About
A1: Item | B1: Value / note
A2: Company | B2: Vandelay Industries, Inc. Legal Department roster export, all locations, as of the date below.
A3: As-of date | B3: 46274
A4: Archstone 9 relaunch training start | B4: 45383
A5: Current Archstone DMS term ends (Amendment No. 2) | B5: 46446
A6: Document management system | B6: Archstone DMS (vendor: Archstone Software, Inc.)
A7: Email domain | B7: vandelay.example (reserved domain; addresses do not resolve)
A8: Employee ID | B8: VL-1001 onward. HR identifier; also stamped on DMS accounts at provisioning, LMS records, and service-desk tickets.
A9: Cohort key | B9: practice_group | level_band. The Legal Technology Pulse Survey is anonymous and reports at this cohort level; usage and training records are per employee_id and roll up to the same key.
A10: Geography | B10: HQ New York. Regional US offices: Chicago, Houston, Washington DC, San Francisco, Atlanta, Los Angeles. International: London, Dublin, Singapore, Mexico City.
A11: Tenure | B11: hire_date is the HR date of hire. tenure_years is computed as of the as-of date. joined_after_relaunch flags staff hired after the Archstone 9 relaunch training began (April 2024).
A12: Formulas | B12: tenure_years, joined_after_relaunch, manager_name, cohort_key, and the counts on the Summary and Taxonomy sheets are live formulas.
