Workbook

Sheet Panel
A1: panel_id | B1: industry | C1: region | D1: legal_dept_users | E1: dms_platform | F1: effective_price_per_user_month_usd | G1: satisfaction_1_to_5 | H1: evaluating_alternatives_next_12m | I1: contract_has_ai_data_use_clause | J1: ai_clause_tenant_scoped_only | K1: last_renewal_proposed_uplift_pct | L1: last_renewal_negotiated_uplift_pct | M1: ran_competitive_check_before_renewal | N1: notice_period_days | O1: sla_measurement_period | P1: last_renewal_year
A2: P001 | B2: Financial services | C2: UK / Ireland | D2: 260 | E2: Pied Piper Vault | F2: 37.22 | G2: 4.6 | H2: No | I2: No | J2: n/a | K2: 3 | L2: 2 | M2: No | N2: 90 | O2: Annual | P2: 2025
A3: P002 | B3: Healthcare | C3: US | D3: 380 | E3: Pied Piper Vault | F3: 44.05 | G3: 4.4 | H3: No | I3: No | J3: n/a | M3: No | N3: 180 | O3: Monthly | P3: 2026
A4: P003 | B4: Telecommunications | C4: US | D4: 480 | E4: Archstone DMS | F4: 36.62 | G4: 3.2 | H4: No | I4: Yes | J4: No | K4: 22 | L4: 17 | M4: No | N4: 60 | O4: Monthly | P4: 2025
A5: P004 | B5: Telecommunications | C5: EU | D5: 480 | E5: Hooli Docs | F5: 59.72 | G5: 3.7 | H5: No | I5: Yes | J5: No | K5: 8 | L5: 3 | M5: Yes | N5: 60 | O5: Annual | P5: 2025
A6: P005 | B6: Insurance | C6: UK / Ireland | D6: 240 | E6: Other | F6: 34.59 | G6: 2.3 | H6: No | I6: Yes | J6: Yes | K6: 12 | L6: 5 | M6: Yes | N6: 90 | O6: Quarterly | P6: 2025
A7: P006 | B7: Industrial / manufacturing | C7: US | D7: 240 | E7: Other | F7: 31 | G7: 3.3 | H7: No | I7: Yes | J7: Yes | M7: Yes | N7: 120 | O7: Monthly | P7: 2023
A8: P007 | B8: Media | C8: US | D8: 380 | E8: Hooli Docs | F8: 31 | G8: 3.6 | H8: No | I8: No | J8: n/a | M8: No | N8: 120 | O8: Monthly | P8: 2024
A9: P008 | B9: Transportation / logistics | C9: US | D9: 320 | E9: Pied Piper Vault | F9: 39.13 | G9: 4.5 | H9: Yes | I9: No | J9: n/a | K9: 3 | L9: 1 | M9: Yes | N9: 120 | O9: Annual | P9: 2025
A10: P009 | B10: Technology | C10: US | D10: 480 | E10: Archstone DMS | F10: 49.57 | G10: 3.7 | H10: No | I10: Yes | J10: Yes | K10: 22 | L10: 17 | M10: No | N10: 120 | O10: Quarterly | P10: 2023
A11: P010 | B11: Industrial / manufacturing | C11: US | D11: 280 | E11: Hooli Docs | F11: 31 | G11: 3.4 | H11: No | I11: No | J11: n/a | M11: Yes | N11: 180 | O11: Quarterly | P11: 2025
A12: P011 | B12: Technology | C12: US | D12: 210 | E12: Pied Piper Vault | F12: 45.14 | G12: 4.4 | H12: No | I12: Yes | J12: Yes | K12: 6 | L12: 2 | M12: Yes | N12: 120 | O12: Annual | P12: 2024
A13: P012 | B13: Energy | C13: US | D13: 190 | E13: Other | F13: 57.99 | G13: 1.9 | H13: No | I13: Yes | J13: Yes | K13: 10 | L13: 9 | M13: No | N13: 120 | O13: Quarterly | P13: 2026
A14: P013 | B14: Telecommunications | C14: US | D14: 300 | E14: Archstone DMS | F14: 46.82 | G14: 3.9 | H14: Yes | I14: Yes | J14: Yes | K14: 18 | L14: 6 | M14: Yes | N14: 90 | O14: Annual | P14: 2026
A15: P014 | B15: Retail / consumer | C15: US | D15: 240 | E15: Archstone DMS | F15: 46.41 | G15: 2.4 | H15: No | I15: No | J15: n/a | K15: 15 | L15: 4 | M15: Yes | N15: 120 | O15: Annual | P15: 2026
A16: P015 | B16: Technology | C16: US | D16: 450 | E16: Archstone DMS | F16: 55.64 | G16: 2.8 | H16: No | I16: Yes | J16: Yes | K16: 18 | L16: 15 | M16: No | N16: 120 | O16: Quarterly | P16: 2024
A17: P016 | B17: Energy | C17: US | D17: 450 | E17: Other | F17: 40.2 | G17: 2.2 | H17: No | I17: No | J17: n/a | K17: 12 | L17: 3 | M17: Yes | N17: 120 | O17: Monthly | P17: 2024
A18: P017 | B18: Telecommunications | C18: US | D18: 260 | E18: Hooli Docs | F18: 31 | G18: 3 | H18: No | I18: No | J18: n/a | K18: 6 | L18: 3 | M18: Yes | N18: 90 | O18: Monthly | P18: 2024
A19: P018 | B19: Energy | C19: Canada | D19: 300 | E19: Other | F19: 45.77 | G19: 3 | H19: Yes | I19: Yes | J19: Yes | M19: No | N19: 90 | O19: Quarterly | P19: 2026
A20: P019 | B20: Healthcare | C20: US | D20: 410 | E20: Hooli Docs | F20: 31 | G20: 3.1 | H20: No | I20: Yes | J20: No | K20: 0 | L20: 0 | M20: No | N20: 60 | O20: Annual | P20: 2024
A21: P020 | B21: Healthcare | C21: US | D21: 450 | E21: Archstone DMS | F21: 41.42 | G21: 3.6 | H21: Yes | I21: Yes | J21: Yes | K21: 16 | L21: 4 | M21: Yes | N21: 90 | O21: Annual | P21: 2023
A22: P021 | B22: Healthcare | C22: US | D22: 240 | E22: Archstone DMS | F22: 32.94 | G22: 3.7 | H22: No | I22: Yes | J22: Yes | K22: 20 | L22: 19 | M22: No | N22: 90 | O22: Monthly | P22: 2026
A23: P022 | B23: Media | C23: US | D23: 480 | E23: Archstone DMS | F23: 37.85 | G23: 2.8 | H23: Yes | I23: Yes | J23: No | K23: 15 | L23: 12 | M23: No | N23: 90 | O23: Monthly | P23: 2024
A24: P023 | B24: Media | C24: US | D24: 210 | E24: Archstone DMS | F24: 51.56 | G24: 3.9 | H24: No | I24: Yes | J24: Yes | K24: 15 | L24: 4 | M24: Yes | N24: 120 | O24: Annual | P24: 2026
A25: P024 | B25: Financial services | C25: US | D25: 160 | E25: Hooli Docs | F25: 33.62 | G25: 3.7 | H25: No | I25: No | J25: n/a | K25: 5 | L25: 1 | M25: Yes | N25: 60 | O25: Monthly | P25: 2026
A26: P025 | B26: Financial services | C26: US | D26: 240 | E26: Hooli Docs | F26: 63.2 | G26: 3.6 | H26: No | I26: Yes | J26: Yes | K26: 6 | L26: 2 | M26: Yes | N26: 60 | O26: Monthly | P26: 2023
A27: P026 | B27: Industrial / manufacturing | C27: US | D27: 190 | E27: Archstone DMS | F27: 40.77 | G27: 3.5 | H27: No | I27: Yes | J27: Yes | K27: 18 | L27: 15 | M27: No | N27: 90 | O27: Monthly | P27: 2025
A28: P027 | B28: Transportation / logistics | C28: UK / Ireland | D28: 320 | E28: Archstone DMS | F28: 42.21 | G28: 3.3 | H28: No | I28: Yes | J28: Yes | K28: 20 | L28: 8 | M28: Yes | N28: 90 | O28: Monthly | P28: 2023
A29: P028 | B29: Insurance | C29: US | D29: 160 | E29: Pied Piper Vault | F29: 55.56 | G29: 3.4 | H29: No | I29: No | J29: n/a | K29: 3 | L29: 1 | M29: Yes | N29: 90 | O29: Annual | P29: 2023
A30: P029 | B30: Energy | C30: EU | D30: 380 | E30: Archstone DMS | F30: 48.7 | G30: 4.3 | H30: No | I30: No | J30: n/a | K30: 16 | L30: 11 | M30: No | N30: 90 | O30: Annual | P30: 2024
A31: P030 | B31: Technology | C31: US | D31: 260 | E31: Pied Piper Vault | F31: 34.98 | G31: 3.4 | H31: No | I31: Yes | J31: Yes | K31: 3 | L31: 1 | M31: Yes | N31: 60 | O31: Annual | P31: 2025
... A38: P037 | B38: Energy | C38: US | D38: 410 | E38: Archstone DMS | F38: 47.76 | G38: 3.1 | H38: No | I38: Yes | J38: Yes | K38: 18 | L38: 14 | M38: No | N38: 180 | O38: Monthly | P38: 2025
A39: P038 | B39: Industrial / manufacturing | C39: US | D39: 160 | E39: Pied Piper Vault | F39: 46.38 | G39: 3.8 | H39: No | I39: Yes | J39: Yes | M39: No | N39: 120 | O39: Annual | P39: 2024
A40: P039 | B40: Energy | C40: UK / Ireland | D40: 175 | E40: Pied Piper Vault | F40: 53.32 | G40: 3.6 | H40: Yes | I40: No | J40: n/a | M40: Yes | N40: 90 | O40: Monthly | P40: 2025
A41: P040 | B41: Financial services | C41: Canada | D41: 225 | E41: Pied Piper Vault | F41: 53.01 | G41: 4.6 | H41: No | I41: Yes | J41: Yes | K41: 3 | L41: 3 | M41: No | N41: 90 | O41: Quarterly | P41: 2024
A42: P041 | B42: Healthcare | C42: UK / Ireland | D42: 210 | E42: Archstone DMS | F42: 47.84 | G42: 3.5 | H42: No | I42: No | J42: n/a | K42: 14 | L42: 9 | M42: No | N42: 180 | O42: Annual | P42: 2023
A43: P042 | B43: Industrial / manufacturing | C43: US | D43: 480 | E43: Pied Piper Vault | F43: 41.31 | G43: 4.5 | H43: No | I43: Yes | J43: Yes | M43: No | N43: 60 | O43: Monthly | P43: 2024
A44: P043 | B44: Technology | C44: US | D44: 240 | E44: Archstone DMS | F44: 52.46 | G44: 3.6 | H44: Yes | I44: No | J44: n/a | K44: 20 | L44: 5 | M44: Yes | N44: 120 | O44: Quarterly | P44: 2025
A45: P044 | B45: Media | C45: US | D45: 300 | E45: Hooli Docs | F45: 66 | G45: 3 | H45: No | I45: Yes | J45: No | K45: 3 | L45: 2 | M45: No | N45: 90 | O45: Annual | P45: 2025
A46: P045 | B46: Technology | C46: US | D46: 380 | E46: Hooli Docs | F46: 61.65 | G46: 3.9 | H46: No | I46: No | J46: n/a | K46: 5 | L46: 1 | M46: Yes | N46: 60 | O46: Quarterly | P46: 2026
...

Sheet Summary
A1: Metric | B1: All platforms | C1: Archstone DMS | D1: Hooli Docs | E1: Pied Piper Vault
A2: Departments in panel | B2: =COUNTA(Panel!A2:A61) -> 60 | C2: =COUNTIF(Panel!$E$2:$E$61,"Archstone DMS") -> 25 | D2: =COUNTIF(Panel!$E$2:$E$61,"Hooli Docs") -> 16 | E2: =COUNTIF(Panel!$E$2:$E$61,"Pied Piper Vault") -> 12
A3: Effective price per user per month, mean | B3: =ROUND(AVERAGE(Panel!F2:F61),2) -> 43.33 | C3: =IFERROR(ROUND(AVERAGEIF(Panel!$E$2:$E$61,"Archstone DMS",Panel!F2:F61),2),"") -> 45.52 | D3: =IFERROR(ROUND(AVERAGEIF(Panel!$E$2:$E$61,"Hooli Docs",Panel!F2:F61),2),"") -> 41.09 | E3: =IFERROR(ROUND(AVERAGEIF(Panel!$E$2:$E$61,"Pied Piper Vault",Panel!F2:F61),2),"") -> 43.82
A4: Effective price, 25th percentile | B4: =ROUND(PERCENTILE(Panel!F2:F61,0.25),2) -> 34.88
A5: Effective price, median | B5: =ROUND(MEDIAN(Panel!F2:F61),2) -> 43.79
A6: Effective price, 75th percentile | B6: =ROUND(PERCENTILE(Panel!F2:F61,0.75),2) -> 48.92
A7: Satisfaction, mean (1 to 5) | B7: =ROUND(AVERAGE(Panel!G2:G61),2) -> 3.49 | C7: =IFERROR(ROUND(AVERAGEIF(Panel!$E$2:$E$61,"Archstone DMS",Panel!G2:G61),2),"") -> 3.45 | D7: =IFERROR(ROUND(AVERAGEIF(Panel!$E$2:$E$61,"Hooli Docs",Panel!G2:G61),2),"") -> 3.38 | E7: =IFERROR(ROUND(AVERAGEIF(Panel!$E$2:$E$61,"Pied Piper Vault",Panel!G2:G61),2),"") -> 4.14
A8: Share evaluating alternatives in next 12 months | B8: =COUNTIF(Panel!H2:H61,"Yes")/COUNTA(Panel!H2:H61) -> 0.18333333 | C8: =IFERROR(COUNTIFS(Panel!$E$2:$E$61,"Archstone DMS",Panel!H2:H61,"Yes")/COUNTIF(Panel!$E$2:$E$61,"Archstone DMS"),"") -> 0.28 | D8: =IFERROR(COUNTIFS(Panel!$E$2:$E$61,"Hooli Docs",Panel!H2:H61,"Yes")/COUNTIF(Panel!$E$2:$E$61,"Hooli Docs"),"") -> 0.0625 | E8: =IFERROR(COUNTIFS(Panel!$E$2:$E$61,"Pied Piper Vault",Panel!H2:H61,"Yes")/COUNTIF(Panel!$E$2:$E$61,"Pied Piper Vault"),"") -> 0.16666667
A9: Share with an AI data-use clause | B9: =COUNTIF(Panel!I2:I61,"Yes")/COUNTA(Panel!I2:I61) -> 0.65
A10: Of those, share tenant-scoped only | B10: =IFERROR(COUNTIF(Panel!J2:J61,"Yes")/COUNTIF(Panel!I2:I61,"Yes"),"") -> 0.79487179
A11: Median proposed uplift at last renewal (%) | B11: =MEDIAN(Panel!K2:K61) -> 12
A12: Median negotiated uplift, ran competitive check (%) | B12: {=MEDIAN(IF(Panel!$M$2:$M$61="Yes",Panel!L2:L61))} -> 3
A13: Median negotiated uplift, no competitive check (%) | B13: {=MEDIAN(IF(Panel!$M$2:$M$61="No",Panel!L2:L61))} -> 9
A14: Share with notice period of 120 days or more | B14: =COUNTIF(Panel!N2:N61,">=120")/COUNTA(Panel!N2:N61) -> 0.38333333
A15: Share with annual SLA measurement | B15: =COUNTIF(Panel!O2:O61,"Annual")/COUNTA(Panel!O2:O61) -> 0.38333333

Sheet About
A1: Item | B1: Note
A2: Source | B2: Northstar Legal Technology Index, Corporate Legal DMS Peer Poll 2026. Fielded May to June 2026 among corporate legal departments with 150 to 500 legal staff. 60 responding departments; identities anonymized.
A3: Effective price | B3: Negotiated per-user monthly price for the core DMS excluding storage, professional services, and premium support, as reported by the department. For suite modules this is the incremental price under the enterprise agreement where one exists.
A4: Uplift | B4: Proposed and negotiated percentage increases at the department's most recent renewal. Blank where the department has not yet renewed on the current platform.
A5: Use | B5: Provided to Vandelay Legal Operations under Northstar's member license. Not for redistribution.
