Workbook

Sheet Responses
A1: response_id | B1: submitted | C1: cohort_key | D1: region | E1: tenure_band | F1: q1_finding_documents | G1: q2_outlook_filing | H1: q3_mobile_access | I1: q4_search_quality | J1: q5_speed_performance | K1: q6_support_responsiveness | L1: q7_training_adequacy | M1: q8_overall_satisfaction | N1: recommend_0_10 | O1: understands_insight_ai | P1: what_works_well | Q1: what_is_lacking
A2: R0001 | B2: 46210 | C2: Regulatory & Trade Compliance | Lawyer - Junior | D2: US | E2: 5 to 10 years | F2: 3 | G2: 3 | H2: 2 | I2: 3 | J2: 4 | K2: 2 | L2: 2 | M2: 4 | N2: 6 | O2: No / unsure | Q2: Filing email is more clicks than it should be, so I do not do it.
A3: R0002 | B3: 46222 | C3: Privacy & Data Protection | Lawyer - Senior | D3: US | E3: Under 2 years | F3: 3 | G3: 2 | H3: 2 | I3: 3 | J3: 2 | K3: 1 | L3: 1 | M3: 3 | N3: 4 | O3: Yes | Q3: I was never trained on the new version. I taught myself and I am sure I am doing it wrong.
A4: R0003 | B4: 46213 | C4: Employment & Labor | Lawyer - Mid | D4: US | E4: Under 2 years | F4: 1 | G4: 1 | H4: 2 | I4: 1 | J4: 2 | K4: 2 | L4: 1 | M4: 2 | N4: 1 | O4: No / unsure | Q4: Onboarding gave me a login and a link to a video. That was it.
A5: R0004 | B5: 46225 | C5: Privacy & Data Protection | Lawyer - Mid | D5: UK/Ireland | E5: 2 to 5 years | F5: 3 | G5: 3 | H5: 3 | I5: 4 | J5: 2 | K5: 3 | L5: 3 | M5: 3 | N5: 4 | O5: Yes | P5: Works for what I need, which is not much. | Q5: Painfully slow from the London office in the afternoon.
A6: R0005 | B6: 46215 | C6: Corporate, Securities & Governance | Lawyer - Junior | D6: US | E6: 10+ years | F6: 2 | G6: 3 | H6: 2 | I6: 1 | J6: 3 | K6: 1 | L6: 1 | M6: 1 | N6: 3 | O6: Yes | Q6: I was never trained on the new version. I taught myself and I am sure I am doing it wrong.
A7: R0006 | B7: 46217 | C7: Commercial & Transactions | Lawyer - Mid | D7: US | E7: 2 to 5 years | F7: 4 | G7: 1 | H7: 2 | I7: 2 | J7: 3 | K7: 3 | L7: 2 | M7: 2 | N7: 5 | O7: Yes | P7: The mobile app is good enough for reading on the train. | Q7: Nobody in Employment uses it consistently, so half the file is in email anyway.
A8: R0007 | B8: 46225 | C8: Legal Operations | Legal Ops - Staff | D8: US | E8: 10+ years | F8: 3 | G8: 2 | H8: 2 | I8: 3 | J8: 3 | K8: 3 | L8: 3 | M8: 3 | N8: 6 | O8: No / unsure | Q8: I was never trained on the new version. I taught myself and I am sure I am doing it wrong.
A9: R0008 | B9: 46209 | C9: Litigation & Disputes | Lawyer - Senior | D9: US | E9: 2 to 5 years | F9: 4 | G9: 3 | H9: 3 | I9: 3 | J9: 5 | K9: 4 | L9: 3 | M9: 3 | N9: 9 | O9: Yes | P9: Works for what I need, which is not much. | Q9: The March search problem lasted three days and we had a filing deadline.
A10: R0009 | B10: 46216 | C10: Corporate, Securities & Governance | Lawyer - Mid | D10: US | E10: 10+ years | F10: 4 | G10: 3 | H10: 4 | I10: 2 | J10: 3 | K10: 4 | L10: 2 | M10: 2 | N10: 6 | O10: No / unsure | P10: Adequate. | Q10: I was never trained on the new version. I taught myself and I am sure I am doing it wrong.
A11: R0010 | B11: 46225 | C11: Commercial & Transactions | Executive Assistant | D11: US | E11: Under 2 years | F11: 4 | G11: 5 | H11: 4 | I11: 3 | J11: 4 | K11: 3 | L11: 2 | M11: 5 | N11: 6 | O11: No / unsure | P11: The mobile app is good enough for reading on the train.
A12: R0011 | B12: 46220 | C12: Commercial & Transactions | Lawyer - Mid | D12: US | E12: Under 2 years | F12: 2 | G12: 4 | H12: 3 | I12: 3 | J12: 3 | K12: 2 | L12: 2 | M12: 3 | N12: 6 | O12: Yes | Q12: Support used to respond the same day. Now it is a week.
A13: R0012 | B13: 46214 | C13: Commercial & Transactions | Lawyer - Junior | D13: US | E13: 5 to 10 years | F13: 5 | G13: 3 | H13: 4 | I13: 3 | J13: 3 | K13: 2 | L13: 3 | M13: 4 | N13: 6 | O13: Yes | P13: Fine. | Q13: Search is unpredictable. I usually end up asking a paralegal.
A14: R0013 | B14: 46213 | C14: Commercial & Transactions | Lawyer - Mid | D14: US | E14: Under 2 years | F14: 3 | G14: 4 | H14: 2 | I14: 2 | J14: 2 | K14: 1 | L14: 1 | M14: 2 | N14: 4 | O14: No / unsure | Q14: I was never trained on the new version. I taught myself and I am sure I am doing it wrong.
A15: R0014 | B15: 46214 | C15: Regulatory & Trade Compliance | Paraprofessional | D15: US | E15: Under 2 years | F15: 4 | G15: 3 | H15: 3 | I15: 1 | J15: 3 | K15: 4 | L15: 2 | M15: 4 | N15: 4 | O15: Yes | P15: Works for what I need, which is not much. | Q15: Onboarding gave me a login and a link to a video. That was it.
A16: R0015 | B16: 46225 | C16: Real Estate, Environmental & Safety | Lawyer - Senior | D16: US | E16: 2 to 5 years | F16: 2 | G16: 2 | H16: 1 | I16: 1 | J16: 1 | K16: 1 | L16: 1 | M16: 1 | N16: 0 | O16: Yes | Q16: I still do not understand what the AI feature is supposed to do.
A17: R0016 | B17: 46215 | C17: Litigation & Disputes | Paraprofessional | D17: US | E17: Under 2 years | F17: 4 | G17: 4 | H17: 3 | I17: 4 | J17: 4 | K17: 2 | L17: 2 | M17: 4 | N17: 7 | O17: No / unsure | P17: Fine. | Q17: Onboarding gave me a login and a link to a video. That was it.
A18: R0017 | B18: 46211 | C18: Litigation & Disputes | Paraprofessional | D18: US | E18: 5 to 10 years | F18: 4 | G18: 3 | H18: 3 | I18: 3 | J18: 4 | K18: 5 | L18: 3 | M18: 5 | N18: 8 | O18: Yes | P18: Version control has saved me more than once.
A19: R0018 | B19: 46213 | C19: Litigation & Disputes | Lawyer - Senior | D19: US | E19: 2 to 5 years | F19: 4 | G19: 5 | H19: 5 | I19: 3 | J19: 4 | K19: 3 | L19: 4 | M19: 4 | N19: 8 | O19: Yes | P19: Sharing a workspace with outside counsel saves us hours every week.
A20: R0019 | B20: 46224 | C20: Commercial & Transactions | Lawyer - Senior | D20: US | E20: 10+ years | F20: 3 | G20: 4 | H20: 4 | I20: 3 | J20: 3 | K20: 4 | L20: 2 | M20: 3 | N20: 6 | O20: No / unsure | P20: Fine. | Q20: Support used to respond the same day. Now it is a week.
A21: R0020 | B21: 46221 | C21: Employment & Labor | Lawyer - Junior | D21: US | E21: 10+ years | F21: 3 | G21: 2 | H21: 2 | I21: 2 | J21: 1 | K21: 1 | L21: 2 | M21: 2 | N21: 1 | O21: No / unsure | Q21: I was never trained on the new version. I taught myself and I am sure I am doing it wrong.
A22: R0021 | B22: 46220 | C22: Privacy & Data Protection | Lawyer - Leadership | D22: UK/Ireland | E22: 10+ years | F22: 3 | G22: 4 | H22: 3 | I22: 3 | J22: 3 | K22: 2 | L22: 4 | M22: 3 | N22: 5 | O22: Yes | P22: It does the job. | Q22: Painfully slow from the London office in the afternoon.
A23: R0022 | B23: 46218 | C23: Intellectual Property | Paraprofessional | D23: US | E23: 10+ years | F23: 4 | G23: 5 | H23: 4 | I23: 4 | J23: 4 | K23: 3 | L23: 3 | M23: 4 | N23: 6 | O23: No / unsure | P23: Search is fine once you learn the filters.
A24: R0023 | B24: 46226 | C24: Commercial & Transactions | Paraprofessional | D24: US | E24: 10+ years | F24: 4 | G24: 4 | H24: 4 | I24: 4 | J24: 4 | K24: 4 | L24: 4 | M24: 4 | N24: 7 | O24: Yes | P24: Version control has saved me more than once. | Q24: The March search problem lasted three days and we had a filing deadline.
A25: R0024 | B25: 46218 | C25: Employment & Labor | Lawyer - Junior | D25: US | E25: 10+ years | F25: 2 | G25: 3 | H25: 2 | I25: 3 | J25: 3 | K25: 1 | L25: 1 | M25: 2 | N25: 3 | O25: Yes | Q25: Singapore latency makes large documents unusable in the morning.
A26: R0025 | B26: 46214 | C26: Office of the General Counsel | Executive Assistant | D26: US | E26: 5 to 10 years | F26: 4 | G26: 4 | H26: 5 | I26: 3 | J26: 3 | K26: 3 | L26: 5 | M26: 5 | N26: 7 | O26: Yes | P26: Version control has saved me more than once. | Q26: Search is unpredictable. I usually end up asking a paralegal.
A27: R0026 | B27: 46219 | C27: Corporate, Securities & Governance | Executive Assistant | D27: US | E27: 5 to 10 years | F27: 5 | G27: 4 | H27: 4 | I27: 3 | J27: 3 | K27: 4 | L27: 4 | M27: 4 | N27: 7 | O27: No / unsure | P27: Outlook filing is the best part. One click and the email is on the matter.
A28: R0027 | B28: 46216 | C28: Commercial & Transactions | Executive Assistant | D28: US | E28: Under 2 years | F28: 4 | G28: 3 | H28: 4 | I28: 3 | J28: 2 | K28: 2 | L28: 2 | M28: 4 | N28: 4 | O28: No / unsure | P28: It does the job. | Q28: Singapore latency makes large documents unusable in the morning.
A29: R0028 | B29: 46216 | C29: Commercial & Transactions | Lawyer - Leadership | D29: US | E29: 10+ years | F29: 4 | G29: 4 | H29: 3 | I29: 4 | J29: 4 | K29: 3 | L29: 4 | M29: 4 | N29: 6 | O29: No / unsure | P29: Sharing a workspace with outside counsel saves us hours every week. | Q29: I would use it more if I knew what I was doing in it.
A30: R0029 | B30: 46209 | C30: Commercial & Transactions | Paraprofessional | D30: US | E30: Under 2 years | F30: 3 | G30: 4 | H30: 4 | I30: 4 | J30: 3 | K30: 3 | L30: 1 | M30: 4 | N30: 6 | O30: No / unsure | P30: Works for what I need, which is not much. | Q30: Painfully slow from the London office in the afternoon.
A31: R0030 | B31: 46223 | C31: Legal Operations | Legal Ops - Staff | D31: US | E31: 2 to 5 years | F31: 5 | G31: 3 | H31: 4 | I31: 4 | J31: 4 | K31: 1 | L31: 3 | M31: 4 | N31: 6 | O31: Yes | P31: Fine. | Q31: I was never trained on the new version. I taught myself and I am sure I am doing it wrong.
A32: R0031 | B32: 46215 | C32: Legal Operations | Legal Ops - Staff | D32: US | E32: 10+ years | F32: 5 | G32: 3 | H32: 3 | I32: 4 | J32: 5 | K32: 4 | L32: 3 | M32: 4 | N32: 7 | O32: No / unsure | P32: The paralegals have this dialed in. Follow their folder conventions and everything is easy.
A33: R0032 | B33: 46223 | C33: Litigation & Disputes | Lawyer - Junior | D33: US | E33: Under 2 years | F33: 2 | G33: 2 | H33: 3 | I33: 3 | J33: 3 | K33: 2 | L33: 2 | M33: 3 | N33: 4 | O33: No / unsure | Q33: The mobile app logs me out constantly.
A34: R0033 | B34: 46221 | C34: Legal Operations | Legal Ops - Leadership | D34: US | E34: 5 to 10 years | F34: 3 | G34: 3 | H34: 3 | I34: 3 | J34: 5 | K34: 4 | L34: 3 | M34: 3 | N34: 6 | O34: Yes | P34: Adequate. | Q34: The March search problem lasted three days and we had a filing deadline.
A35: R0034 | B35: 46226 | C35: Legal Operations | Legal Ops - Leadership | D35: US | E35: 5 to 10 years | F35: 4 | G35: 3 | H35: 4 | I35: 4 | J35: 4 | K35: 3 | L35: 1 | M35: 4 | N35: 7 | O35: No / unsure | P35: Works for what I need, which is not much. | Q35: Search is unpredictable. I usually end up asking a paralegal.
A36: R0035 | B36: 46217 | C36: Corporate, Securities & Governance | Paraprofessional | D36: US | E36: Under 2 years | F36: 3 | G36: 4 | H36: 3 | I36: 2 | J36: 3 | K36: 1 | L36: 1 | M36: 3 | N36: 4 | O36: No / unsure | P36: Reliable, except for that outage in November. | Q36: It went down for most of a day last November and nobody told us why.
A37: R0036 | B37: 46212 | C37: Commercial & Transactions | Lawyer - Mid | D37: US | E37: 10+ years | F37: 4 | G37: 3 | H37: 3 | I37: 2 | J37: 4 | K37: 4 | L37: 3 | M37: 4 | N37: 6 | O37: No / unsure | P37: Adequate. | Q37: I still do not understand what the AI feature is supposed to do.
A38: R0037 | B38: 46210 | C38: Commercial & Transactions | Lawyer - Mid | D38: US | E38: 5 to 10 years | F38: 5 | G38: 3 | H38: 2 | I38: 4 | J38: 5 | K38: 4 | L38: 3 | M38: 4 | N38: 8 | O38: Yes | P38: Being able to see the whole matter file in one place is why I use it all day.
A39: R0038 | B39: 46211 | C39: Employment & Labor | Lawyer - Senior | D39: US | E39: Under 2 years | F39: 2 | G39: 1 | H39: 2 | I39: 2 | J39: 2 | K39: 1 | L39: 1 | M39: 1 | N39: 1 | O39: No / unsure | Q39: I was never trained on the new version. I taught myself and I am sure I am doing it wrong.
A40: R0039 | B40: 46223 | C40: Regulatory & Trade Compliance | Paraprofessional | D40: LATAM | E40: 10+ years | F40: 4 | G40: 3 | H40: 4 | I40: 3 | J40: 5 | K40: 3 | L40: 3 | M40: 3 | N40: 6 | O40: Yes | P40: No strong opinion. | Q40: It went down for most of a day last November and nobody told us why.
...

Sheet Questions
A1: Column | B1: Question text | C1: Scale
A2: q1_finding_documents | B2: I can find the documents I need quickly. | C2: 1 = Strongly disagree, 5 = Strongly agree
A3: q2_outlook_filing | B3: Filing email from Outlook works well for me. | C3: 1 = Strongly disagree, 5 = Strongly agree
A4: q3_mobile_access | B4: I can get to what I need from my phone or tablet. | C4: 1 = Strongly disagree, 5 = Strongly agree
A5: q4_search_quality | B5: Search returns the right results. | C5: 1 = Strongly disagree, 5 = Strongly agree
A6: q5_speed_performance | B6: The system is fast and responsive. | C6: 1 = Strongly disagree, 5 = Strongly agree
A7: q6_support_responsiveness | B7: When I have a problem, I get help quickly. | C7: 1 = Strongly disagree, 5 = Strongly agree
A8: q7_training_adequacy | B8: I received the training I needed to use the system well. | C8: 1 = Strongly disagree, 5 = Strongly agree
A9: q8_overall_satisfaction | B9: Overall, I am satisfied with our document management system. | C9: 1 = Strongly disagree, 5 = Strongly agree
A10: recommend_0_10 | B10: How likely are you to recommend our document management system to a colleague joining the department? | C10: 0 to 10
A11: understands_insight_ai | B11: Do you understand what the Insight AI features do and when to use them? | C11: Yes / No or unsure
A12: what_works_well | B12: What works well? | C12: Free text
A13: what_is_lacking | B13: What is lacking or frustrating? | C13: Free text

Sheet By Cohort
A1: cohort_key | B1: responses | C1: q1_finding_documents | D1: q2_outlook_filing | E1: q3_mobile_access | F1: q4_search_quality | G1: q5_speed_performance | H1: q6_support_responsiveness | I1: q7_training_adequacy | J1: q8_overall_satisfaction | K1: recommend_avg
A2: Commercial & Transactions | Executive Assistant | B2: =COUNTIF(Responses!$C$2:$C$159,A2) -> 2 | C2: =IFERROR(ROUND(AVERAGEIF(Responses!$C$2:$C$159,$A2,Responses!F$2:F$159),2),"") -> 4 | D2: =IFERROR(ROUND(AVERAGEIF(Responses!$C$2:$C$159,$A2,Responses!G$2:G$159),2),"") -> 4 | E2: =IFERROR(ROUND(AVERAGEIF(Responses!$C$2:$C$159,$A2,Responses!H$2:H$159),2),"") -> 4 | F2: =IFERROR(ROUND(AVERAGEIF(Responses!$C$2:$C$159,$A2,Responses!I$2:I$159),2),"") -> 3 | G2: =IFERROR(ROUND(AVERAGEIF(Responses!$C$2:$C$159,$A2,Responses!J$2:J$159),2),"") -> 3 | H2: =IFERROR(ROUND(AVERAGEIF(Responses!$C$2:$C$159,$A2,Responses!K$2:K$159),2),"") -> 2.5 | I2: =IFERROR(ROUND(AVERAGEIF(Responses!$C$2:$C$159,$A2,Responses!L$2:L$159),2),"") -> 2 | J2: =IFERROR(ROUND(AVERAGEIF(Responses!$C$2:$C$159,$A2,Responses!M$2:M$159),2),"") -> 4.5 | K2: =IFERROR(ROUND(AVERAGEIF(Responses!$C$2:$C$159,$A2,Responses!N$2:N$159),2),"") -> 5
A3: Commercial & Transactions | Lawyer - Junior | B3: =COUNTIF(Responses!$C$2:$C$159,A3) -> 8 | C3: =IFERROR(ROUND(AVERAGEIF(Responses!$C$2:$C$159,$A3,Responses!F$2:F$159),2),"") -> 3.5 | D3: =IFERROR(ROUND(AVERAGEIF(Responses!$C$2:$C$159,$A3,Responses!G$2:G$159),2),"") -> 2.88 | E3: =IFERROR(ROUND(AVERAGEIF(Responses!$C$2:$C$159,$A3,Responses!H$2:H$159),2),"") -> 2.88 | F3: =IFERROR(ROUND(AVERAGEIF(Responses!$C$2:$C$159,$A3,Responses!I$2:I$159),2),"") -> 3 | G3: =IFERROR(ROUND(AVERAGEIF(Responses!$C$2:$C$159,$A3,Responses!J$2:J$159),2),"") -> 2.75 | H3: =IFERROR(ROUND(AVERAGEIF(Responses!$C$2:$C$159,$A3,Responses!K$2:K$159),2),"") -> 2.63 | I3: =IFERROR(ROUND(AVERAGEIF(Responses!$C$2:$C$159,$A3,Responses!L$2:L$159),2),"") -> 2.88 | J3: =IFERROR(ROUND(AVERAGEIF(Responses!$C$2:$C$159,$A3,Responses!M$2:M$159),2),"") -> 2.88 | K3: =IFERROR(ROUND(AVERAGEIF(Responses!$C$2:$C$159,$A3,Responses!N$2:N$159),2),"") -> 5.13
A4: Commercial & Transactions | Lawyer - Leadership | B4: =COUNTIF(Responses!$C$2:$C$159,A4) -> 1 | C4: =IFERROR(ROUND(AVERAGEIF(Responses!$C$2:$C$159,$A4,Responses!F$2:F$159),2),"") -> 4 | D4: =IFERROR(ROUND(AVERAGEIF(Responses!$C$2:$C$159,$A4,Responses!G$2:G$159),2),"") -> 4 | E4: =IFERROR(ROUND(AVERAGEIF(Responses!$C$2:$C$159,$A4,Responses!H$2:H$159),2),"") -> 3 | F4: =IFERROR(ROUND(AVERAGEIF(Responses!$C$2:$C$159,$A4,Responses!I$2:I$159),2),"") -> 4 | G4: =IFERROR(ROUND(AVERAGEIF(Responses!$C$2:$C$159,$A4,Responses!J$2:J$159),2),"") -> 4 | H4: =IFERROR(ROUND(AVERAGEIF(Responses!$C$2:$C$159,$A4,Responses!K$2:K$159),2),"") -> 3 | I4: =IFERROR(ROUND(AVERAGEIF(Responses!$C$2:$C$159,$A4,Responses!L$2:L$159),2),"") -> 4 | J4: =IFERROR(ROUND(AVERAGEIF(Responses!$C$2:$C$159,$A4,Responses!M$2:M$159),2),"") -> 4 | K4: =IFERROR(ROUND(AVERAGEIF(Responses!$C$2:$C$159,$A4,Responses!N$2:N$159),2),"") -> 6
A5: Commercial & Transactions | Lawyer - Mid | B5: =COUNTIF(Responses!$C$2:$C$159,A5) -> 9 | C5: =IFERROR(ROUND(AVERAGEIF(Responses!$C$2:$C$159,$A5,Responses!F$2:F$159),2),"") -> 3.11 | D5: =IFERROR(ROUND(AVERAGEIF(Responses!$C$2:$C$159,$A5,Responses!G$2:G$159),2),"") -> 3.11 | E5: =IFERROR(ROUND(AVERAGEIF(Responses!$C$2:$C$159,$A5,Responses!H$2:H$159),2),"") -> 2.78 | F5: =IFERROR(ROUND(AVERAGEIF(Responses!$C$2:$C$159,$A5,Responses!I$2:I$159),2),"") -> 3 | G5: =IFERROR(ROUND(AVERAGEIF(Responses!$C$2:$C$159,$A5,Responses!J$2:J$159),2),"") -> 3.11 | H5: =IFERROR(ROUND(AVERAGEIF(Responses!$C$2:$C$159,$A5,Responses!K$2:K$159),2),"") -> 2.89 | I5: =IFERROR(ROUND(AVERAGEIF(Responses!$C$2:$C$159,$A5,Responses!L$2:L$159),2),"") -> 2.67 | J5: =IFERROR(ROUND(AVERAGEIF(Responses!$C$2:$C$159,$A5,Responses!M$2:M$159),2),"") -> 3.33 | K5: =IFERROR(ROUND(AVERAGEIF(Responses!$C$2:$C$159,$A5,Responses!N$2:N$159),2),"") -> 6
A6: Commercial & Transactions | Lawyer - Senior | B6: =COUNTIF(Responses!$C$2:$C$159,A6) -> 5 | C6: =IFERROR(ROUND(AVERAGEIF(Responses!$C$2:$C$159,$A6,Responses!F$2:F$159),2),"") -> 3.2 | D6: =IFERROR(ROUND(AVERAGEIF(Responses!$C$2:$C$159,$A6,Responses!G$2:G$159),2),"") -> 3.4 | E6: =IFERROR(ROUND(AVERAGEIF(Responses!$C$2:$C$159,$A6,Responses!H$2:H$159),2),"") -> 3.2 | F6: =IFERROR(ROUND(AVERAGEIF(Responses!$C$2:$C$159,$A6,Responses!I$2:I$159),2),"") -> 2.8 | G6: =IFERROR(ROUND(AVERAGEIF(Responses!$C$2:$C$159,$A6,Responses!J$2:J$159),2),"") -> 3.4 | H6: =IFERROR(ROUND(AVERAGEIF(Responses!$C$2:$C$159,$A6,Responses!K$2:K$159),2),"") -> 2.8 | I6: =IFERROR(ROUND(AVERAGEIF(Responses!$C$2:$C$159,$A6,Responses!L$2:L$159),2),"") -> 2 | J6: =IFERROR(ROUND(AVERAGEIF(Responses!$C$2:$C$159,$A6,Responses!M$2:M$159),2),"") -> 2.8 | K6: =IFERROR(ROUND(AVERAGEIF(Responses!$C$2:$C$159,$A6,Responses!N$2:N$159),2),"") -> 4.8
A7: Commercial & Transactions | Paraprofessional | B7: =COUNTIF(Responses!$C$2:$C$159,A7) -> 11 | C7: =IFERROR(ROUND(AVERAGEIF(Responses!$C$2:$C$159,$A7,Responses!F$2:F$159),2),"") -> 3.73 | D7: =IFERROR(ROUND(AVERAGEIF(Responses!$C$2:$C$159,$A7,Responses!G$2:G$159),2),"") -> 4.09 | E7: =IFERROR(ROUND(AVERAGEIF(Responses!$C$2:$C$159,$A7,Responses!H$2:H$159),2),"") -> 3.36 | F7: =IFERROR(ROUND(AVERAGEIF(Responses!$C$2:$C$159,$A7,Responses!I$2:I$159),2),"") -> 3.64 | G7: =IFERROR(ROUND(AVERAGEIF(Responses!$C$2:$C$159,$A7,Responses!J$2:J$159),2),"") -> 3.73 | H7: =IFERROR(ROUND(AVERAGEIF(Responses!$C$2:$C$159,$A7,Responses!K$2:K$159),2),"") -> 3.36 | I7: =IFERROR(ROUND(AVERAGEIF(Responses!$C$2:$C$159,$A7,Responses!L$2:L$159),2),"") -> 3.36 | J7: =IFERROR(ROUND(AVERAGEIF(Responses!$C$2:$C$159,$A7,Responses!M$2:M$159),2),"") -> 3.91 | K7: =IFERROR(ROUND(AVERAGEIF(Responses!$C$2:$C$159,$A7,Responses!N$2:N$159),2),"") -> 6.73
A8: Commercial & Transactions | Paraprofessional - Lead | B8: =COUNTIF(Responses!$C$2:$C$159,A8) -> 1 | C8: =IFERROR(ROUND(AVERAGEIF(Responses!$C$2:$C$159,$A8,Responses!F$2:F$159),2),"") -> 5 | D8: =IFERROR(ROUND(AVERAGEIF(Responses!$C$2:$C$159,$A8,Responses!G$2:G$159),2),"") -> 4 | E8: =IFERROR(ROUND(AVERAGEIF(Responses!$C$2:$C$159,$A8,Responses!H$2:H$159),2),"") -> 4 | F8: =IFERROR(ROUND(AVERAGEIF(Responses!$C$2:$C$159,$A8,Responses!I$2:I$159),2),"") -> 5 | G8: =IFERROR(ROUND(AVERAGEIF(Responses!$C$2:$C$159,$A8,Responses!J$2:J$159),2),"") -> 5 | H8: =IFERROR(ROUND(AVERAGEIF(Responses!$C$2:$C$159,$A8,Responses!K$2:K$159),2),"") -> 3 | I8: =IFERROR(ROUND(AVERAGEIF(Responses!$C$2:$C$159,$A8,Responses!L$2:L$159),2),"") -> 3 | J8: =IFERROR(ROUND(AVERAGEIF(Responses!$C$2:$C$159,$A8,Responses!M$2:M$159),2),"") -> 4 | K8: =IFERROR(ROUND(AVERAGEIF(Responses!$C$2:$C$159,$A8,Responses!N$2:N$159),2),"") -> 9
A9: Corporate, Securities & Governance | Executive Assistant | B9: =COUNTIF(Responses!$C$2:$C$159,A9) -> 1 | C9: =IFERROR(ROUND(AVERAGEIF(Responses!$C$2:$C$159,$A9,Responses!F$2:F$159),2),"") -> 5 | D9: =IFERROR(ROUND(AVERAGEIF(Responses!$C$2:$C$159,$A9,Responses!G$2:G$159),2),"") -> 4 | E9: =IFERROR(ROUND(AVERAGEIF(Responses!$C$2:$C$159,$A9,Responses!H$2:H$159),2),"") -> 4 | F9: =IFERROR(ROUND(AVERAGEIF(Responses!$C$2:$C$159,$A9,Responses!I$2:I$159),2),"") -> 3 | G9: =IFERROR(ROUND(AVERAGEIF(Responses!$C$2:$C$159,$A9,Responses!J$2:J$159),2),"") -> 3 | H9: =IFERROR(ROUND(AVERAGEIF(Responses!$C$2:$C$159,$A9,Responses!K$2:K$159),2),"") -> 4 | I9: =IFERROR(ROUND(AVERAGEIF(Responses!$C$2:$C$159,$A9,Responses!L$2:L$159),2),"") -> 4 | J9: =IFERROR(ROUND(AVERAGEIF(Responses!$C$2:$C$159,$A9,Responses!M$2:M$159),2),"") -> 4 | K9: =IFERROR(ROUND(AVERAGEIF(Responses!$C$2:$C$159,$A9,Responses!N$2:N$159),2),"") -> 7
A10: Corporate, Securities & Governance | Lawyer - Junior | B10: =COUNTIF(Responses!$C$2:$C$159,A10) -> 4 | C10: =IFERROR(ROUND(AVERAGEIF(Responses!$C$2:$C$159,$A10,Responses!F$2:F$159),2),"") -> 2.25 | D10: =IFERROR(ROUND(AVERAGEIF(Responses!$C$2:$C$159,$A10,Responses!G$2:G$159),2),"") -> 2 | E10: =IFERROR(ROUND(AVERAGEIF(Responses!$C$2:$C$159,$A10,Responses!H$2:H$159),2),"") -> 1.25 | F10: =IFERROR(ROUND(AVERAGEIF(Responses!$C$2:$C$159,$A10,Responses!I$2:I$159),2),"") -> 2.25 | G10: =IFERROR(ROUND(AVERAGEIF(Responses!$C$2:$C$159,$A10,Responses!J$2:J$159),2),"") -> 2 | H10: =IFERROR(ROUND(AVERAGEIF(Responses!$C$2:$C$159,$A10,Responses!K$2:K$159),2),"") -> 1.25 | I10: =IFERROR(ROUND(AVERAGEIF(Responses!$C$2:$C$159,$A10,Responses!L$2:L$159),2),"") -> 1.25 | J10: =IFERROR(ROUND(AVERAGEIF(Responses!$C$2:$C$159,$A10,Responses!M$2:M$159),2),"") -> 2 | K10: =IFERROR(ROUND(AVERAGEIF(Responses!$C$2:$C$159,$A10,Responses!N$2:N$159),2),"") -> 2
A11: Corporate, Securities & Governance | Lawyer - Mid | B11: =COUNTIF(Responses!$C$2:$C$159,A11) -> 4 | C11: =IFERROR(ROUND(AVERAGEIF(Responses!$C$2:$C$159,$A11,Responses!F$2:F$159),2),"") -> 2.25 | D11: =IFERROR(ROUND(AVERAGEIF(Responses!$C$2:$C$159,$A11,Responses!G$2:G$159),2),"") -> 1.75 | E11: =IFERROR(ROUND(AVERAGEIF(Responses!$C$2:$C$159,$A11,Responses!H$2:H$159),2),"") -> 2.5 | F11: =IFERROR(ROUND(AVERAGEIF(Responses!$C$2:$C$159,$A11,Responses!I$2:I$159),2),"") -> 2 | G11: =IFERROR(ROUND(AVERAGEIF(Responses!$C$2:$C$159,$A11,Responses!J$2:J$159),2),"") -> 2.5 | H11: =IFERROR(ROUND(AVERAGEIF(Responses!$C$2:$C$159,$A11,Responses!K$2:K$159),2),"") -> 3 | I11: =IFERROR(ROUND(AVERAGEIF(Responses!$C$2:$C$159,$A11,Responses!L$2:L$159),2),"") -> 1.5 | J11: =IFERROR(ROUND(AVERAGEIF(Responses!$C$2:$C$159,$A11,Responses!M$2:M$159),2),"") -> 2 | K11: =IFERROR(ROUND(AVERAGEIF(Responses!$C$2:$C$159,$A11,Responses!N$2:N$159),2),"") -> 3
A12: Corporate, Securities & Governance | Lawyer - Senior | B12: =COUNTIF(Responses!$C$2:$C$159,A12) -> 1 | C12: =IFERROR(ROUND(AVERAGEIF(Responses!$C$2:$C$159,$A12,Responses!F$2:F$159),2),"") -> 2 | D12: =IFERROR(ROUND(AVERAGEIF(Responses!$C$2:$C$159,$A12,Responses!G$2:G$159),2),"") -> 3 | E12: =IFERROR(ROUND(AVERAGEIF(Responses!$C$2:$C$159,$A12,Responses!H$2:H$159),2),"") -> 3 | F12: =IFERROR(ROUND(AVERAGEIF(Responses!$C$2:$C$159,$A12,Responses!I$2:I$159),2),"") -> 3 | G12: =IFERROR(ROUND(AVERAGEIF(Responses!$C$2:$C$159,$A12,Responses!J$2:J$159),2),"") -> 3 | H12: =IFERROR(ROUND(AVERAGEIF(Responses!$C$2:$C$159,$A12,Responses!K$2:K$159),2),"") -> 2 | I12: =IFERROR(ROUND(AVERAGEIF(Responses!$C$2:$C$159,$A12,Responses!L$2:L$159),2),"") -> 4 | J12: =IFERROR(ROUND(AVERAGEIF(Responses!$C$2:$C$159,$A12,Responses!M$2:M$159),2),"") -> 3 | K12: =IFERROR(ROUND(AVERAGEIF(Responses!$C$2:$C$159,$A12,Responses!N$2:N$159),2),"") -> 4
A13: Corporate, Securities & Governance | Paraprofessional | B13: =COUNTIF(Responses!$C$2:$C$159,A13) -> 2 | C13: =IFERROR(ROUND(AVERAGEIF(Responses!$C$2:$C$159,$A13,Responses!F$2:F$159),2),"") -> 2.5 | D13: =IFERROR(ROUND(AVERAGEIF(Responses!$C$2:$C$159,$A13,Responses!G$2:G$159),2),"") -> 3.5 | E13: =IFERROR(ROUND(AVERAGEIF(Responses!$C$2:$C$159,$A13,Responses!H$2:H$159),2),"") -> 3 | F13: =IFERROR(ROUND(AVERAGEIF(Responses!$C$2:$C$159,$A13,Responses!I$2:I$159),2),"") -> 2.5 | G13: =IFERROR(ROUND(AVERAGEIF(Responses!$C$2:$C$159,$A13,Responses!J$2:J$159),2),"") -> 3 | H13: =IFERROR(ROUND(AVERAGEIF(Responses!$C$2:$C$159,$A13,Responses!K$2:K$159),2),"") -> 2.5 | I13: =IFERROR(ROUND(AVERAGEIF(Responses!$C$2:$C$159,$A13,Responses!L$2:L$159),2),"") -> 1 | J13: =IFERROR(ROUND(AVERAGEIF(Responses!$C$2:$C$159,$A13,Responses!M$2:M$159),2),"") -> 3 | K13: =IFERROR(ROUND(AVERAGEIF(Responses!$C$2:$C$159,$A13,Responses!N$2:N$159),2),"") -> 5
... A47: Regulatory & Trade Compliance | Paraprofessional | B47: =COUNTIF(Responses!$C$2:$C$159,A47) -> 4 | C47: =IFERROR(ROUND(AVERAGEIF(Responses!$C$2:$C$159,$A47,Responses!F$2:F$159),2),"") -> 3.75 | D47: =IFERROR(ROUND(AVERAGEIF(Responses!$C$2:$C$159,$A47,Responses!G$2:G$159),2),"") -> 3.25 | E47: =IFERROR(ROUND(AVERAGEIF(Responses!$C$2:$C$159,$A47,Responses!H$2:H$159),2),"") -> 3.25 | F47: =IFERROR(ROUND(AVERAGEIF(Responses!$C$2:$C$159,$A47,Responses!I$2:I$159),2),"") -> 2.75 | G47: =IFERROR(ROUND(AVERAGEIF(Responses!$C$2:$C$159,$A47,Responses!J$2:J$159),2),"") -> 4 | H47: =IFERROR(ROUND(AVERAGEIF(Responses!$C$2:$C$159,$A47,Responses!K$2:K$159),2),"") -> 3.5 | I47: =IFERROR(ROUND(AVERAGEIF(Responses!$C$2:$C$159,$A47,Responses!L$2:L$159),2),"") -> 2.75 | J47: =IFERROR(ROUND(AVERAGEIF(Responses!$C$2:$C$159,$A47,Responses!M$2:M$159),2),"") -> 3.75 | K47: =IFERROR(ROUND(AVERAGEIF(Responses!$C$2:$C$159,$A47,Responses!N$2:N$159),2),"") -> 5.5

Sheet Survey Notes
A1: Item | B1: Note
A2: Instrument | B2: Legal Technology Pulse Survey, July 2026. Fielded 6 to 24 July 2026 by Legal Operations with the Training & Enablement Lead. 230 invited, 158 responded (69%).
A3: Anonymity | B3: Responses are anonymous. Each response carries cohort_key (practice group and level band), region, and tenure band so results can be compared with usage and training data at cohort level. No individual identifiers were collected.
A4: Cohort key | B4: Matches the roster's practice_group | level_band and therefore rolls up to the same cohorts as the usage telemetry and LMS export.
A5: Caveat | B5: Cohorts with fewer than 5 responses should be read with care.
